2024-09-19 11:45:51.076 WARNING (SyncWorker_3) [homeassistant.components.local_file.camera] Could not read camera Courtyard_still image from file: /config/www/cam_captures/cam_captures.jpg
2024-09-19 11:45:51.080 WARNING (SyncWorker_6) [homeassistant.components.local_file.camera] Could not read camera Amazon_rekognition image from file: /config/www/amazon-rekognition/rekognition_car_courtyard_still_latest.jpg
2024-09-19 11:45:51.085 WARNING (SyncWorker_2) [homeassistant.components.local_file.camera] Could not read camera Doorbell_still image from file: /config/www/cam_captures/doorbell_captures.jpg
2024-09-19 11:46:13.352 WARNING (MainThread) [aioesphomeapi.reconnect_logic] Can't connect to ESPHome API for sons_blind @ 192.168.0.38: Error connecting to [AddrInfo(family=<AddressFamily.AF_INET: 2>, type=<SocketKind.SOCK_STREAM: 1>, proto=6, sockaddr=IPv4Sockaddr(address='192.168.0.38', port=6053))]: [Errno 113] Connect call failed ('192.168.0.38', 6053) (SocketAPIError)
2024-09-19 11:46:19.597 WARNING (MainThread) [zigpy.application] Zigbee channel 15 utilization is 82.35%!
2024-09-19 11:46:19.597 WARNING (MainThread) [zigpy.application] If you are having problems joining new devices, are missing sensor updates, or have issues keeping devices joined, ensure your coordinator is away from interference sources such as USB 3.0 devices, SSDs, WiFi routers, etc.
2024-09-19 11:46:25.798 ERROR (MainThread) [homeassistant.helpers.event] Error while processing template: Template<template=({{(states('sensor.sons_blind1_position')) | int}}) renders=2>
Traceback (most recent call last):
  File "/usr/src/homeassistant/homeassistant/helpers/template.py", line 604, in async_render
    render_result = _render_with_context(self.template, compiled, **kwargs)
                    ^^^^^^^^^^^^^^^^^^^^^^^^^^^^^^^^^^^^^^^^^^^^^^^^^^^^^^^
  File "/usr/src/homeassistant/homeassistant/helpers/template.py", line 2639, in _render_with_context
    return template.render(**kwargs)
           ^^^^^^^^^^^^^^^^^^^^^^^^^
  File "/usr/local/lib/python3.12/site-packages/jinja2/environment.py", line 1304, in render
    self.environment.handle_exception()
  File "/usr/local/lib/python3.12/site-packages/jinja2/environment.py", line 939, in handle_exception
    raise rewrite_traceback_stack(source=source)
  File "<template>", line 1, in top-level template code
  File "/usr/src/homeassistant/homeassistant/helpers/template.py", line 2277, in forgiving_int_filter
    raise_no_default("int", value)
  File "/usr/src/homeassistant/homeassistant/helpers/template.py", line 1872, in raise_no_default
    raise ValueError(
ValueError: Template error: int got invalid input 'unavailable' when rendering template '{{(states('sensor.sons_blind1_position')) | int}}' but no default was specified

The above exception was the direct cause of the following exception:

Traceback (most recent call last):
  File "/usr/src/homeassistant/homeassistant/helpers/template.py", line 716, in async_render_to_info
    render_info._result = self.async_render(  # noqa: SLF001
                          ^^^^^^^^^^^^^^^^^^^^^^^^^^^^^^^^^^
  File "/usr/src/homeassistant/homeassistant/helpers/template.py", line 606, in async_render
    raise TemplateError(err) from err
homeassistant.exceptions.TemplateError: ValueError: Template error: int got invalid input 'unavailable' when rendering template '{{(states('sensor.sons_blind1_position')) | int}}' but no default was specified
2024-09-19 11:46:25.833 ERROR (MainThread) [homeassistant.helpers.event] Error while processing template: Template<template=({% if states('sensor.sons_blind1_position')|float > 70 %}
    mdi:blinds-open
{% else %}
    mdi:blinds
{% endif %}) renders=3>
Traceback (most recent call last):
  File "/usr/src/homeassistant/homeassistant/helpers/template.py", line 2258, in forgiving_float_filter
    return float(value)
           ^^^^^^^^^^^^
ValueError: could not convert string to float: 'unavailable'

During handling of the above exception, another exception occurred:

Traceback (most recent call last):
  File "/usr/src/homeassistant/homeassistant/helpers/template.py", line 604, in async_render
    render_result = _render_with_context(self.template, compiled, **kwargs)
                    ^^^^^^^^^^^^^^^^^^^^^^^^^^^^^^^^^^^^^^^^^^^^^^^^^^^^^^^
  File "/usr/src/homeassistant/homeassistant/helpers/template.py", line 2639, in _render_with_context
    return template.render(**kwargs)
           ^^^^^^^^^^^^^^^^^^^^^^^^^
  File "/usr/local/lib/python3.12/site-packages/jinja2/environment.py", line 1304, in render
    self.environment.handle_exception()
  File "/usr/local/lib/python3.12/site-packages/jinja2/environment.py", line 939, in handle_exception
    raise rewrite_traceback_stack(source=source)
  File "<template>", line 1, in top-level template code
  File "/usr/src/homeassistant/homeassistant/helpers/template.py", line 2261, in forgiving_float_filter
    raise_no_default("float", value)
  File "/usr/src/homeassistant/homeassistant/helpers/template.py", line 1872, in raise_no_default
    raise ValueError(
ValueError: Template error: float got invalid input 'unavailable' when rendering template '{% if states('sensor.sons_blind1_position')|float > 70 %}
    mdi:blinds-open
{% else %}
    mdi:blinds
{% endif %}' but no default was specified

The above exception was the direct cause of the following exception:

Traceback (most recent call last):
  File "/usr/src/homeassistant/homeassistant/helpers/template.py", line 716, in async_render_to_info
    render_info._result = self.async_render(  # noqa: SLF001
                          ^^^^^^^^^^^^^^^^^^^^^^^^^^^^^^^^^^
  File "/usr/src/homeassistant/homeassistant/helpers/template.py", line 606, in async_render
    raise TemplateError(err) from err
homeassistant.exceptions.TemplateError: ValueError: Template error: float got invalid input 'unavailable' when rendering template '{% if states('sensor.sons_blind1_position')|float > 70 %}
    mdi:blinds-open
{% else %}
    mdi:blinds
{% endif %}' but no default was specified
2024-09-19 11:46:25.844 ERROR (MainThread) [homeassistant.components.template.template_entity] TemplateError('ValueError: Template error: int got invalid input 'unavailable' when rendering template '{{(states('sensor.sons_blind1_position')) | int}}' but no default was specified') while processing template 'Template<template=({{(states('sensor.sons_blind1_position')) | int}}) renders=4>' for attribute '_position' in entity 'cover.sons_blind1'
2024-09-19 11:46:25.845 ERROR (MainThread) [homeassistant.components.template.template_entity] TemplateError('ValueError: Template error: float got invalid input 'unavailable' when rendering template '{% if states('sensor.sons_blind1_position')|float > 70 %}
    mdi:blinds-open
{% else %}
    mdi:blinds
{% endif %}' but no default was specified') while processing template 'Template<template=({% if states('sensor.sons_blind1_position')|float > 70 %}
    mdi:blinds-open
{% else %}
    mdi:blinds
{% endif %}) renders=5>' for attribute '_attr_icon' in entity 'cover.sons_blind1'
2024-09-19 11:46:25.850 ERROR (MainThread) [homeassistant.helpers.event] Error while processing template: Template<template=({{(states('sensor.sons_blind2_position')) | int}}) renders=2>
Traceback (most recent call last):
  File "/usr/src/homeassistant/homeassistant/helpers/template.py", line 604, in async_render
    render_result = _render_with_context(self.template, compiled, **kwargs)
                    ^^^^^^^^^^^^^^^^^^^^^^^^^^^^^^^^^^^^^^^^^^^^^^^^^^^^^^^
  File "/usr/src/homeassistant/homeassistant/helpers/template.py", line 2639, in _render_with_context
    return template.render(**kwargs)
           ^^^^^^^^^^^^^^^^^^^^^^^^^
  File "/usr/local/lib/python3.12/site-packages/jinja2/environment.py", line 1304, in render
    self.environment.handle_exception()
  File "/usr/local/lib/python3.12/site-packages/jinja2/environment.py", line 939, in handle_exception
    raise rewrite_traceback_stack(source=source)
  File "<template>", line 1, in top-level template code
  File "/usr/src/homeassistant/homeassistant/helpers/template.py", line 2277, in forgiving_int_filter
    raise_no_default("int", value)
  File "/usr/src/homeassistant/homeassistant/helpers/template.py", line 1872, in raise_no_default
    raise ValueError(
ValueError: Template error: int got invalid input 'unavailable' when rendering template '{{(states('sensor.sons_blind2_position')) | int}}' but no default was specified

The above exception was the direct cause of the following exception:

Traceback (most recent call last):
  File "/usr/src/homeassistant/homeassistant/helpers/template.py", line 716, in async_render_to_info
    render_info._result = self.async_render(  # noqa: SLF001
                          ^^^^^^^^^^^^^^^^^^^^^^^^^^^^^^^^^^
  File "/usr/src/homeassistant/homeassistant/helpers/template.py", line 606, in async_render
    raise TemplateError(err) from err
homeassistant.exceptions.TemplateError: ValueError: Template error: int got invalid input 'unavailable' when rendering template '{{(states('sensor.sons_blind2_position')) | int}}' but no default was specified
2024-09-19 11:46:25.856 ERROR (MainThread) [homeassistant.helpers.event] Error while processing template: Template<template=({% if states('sensor.sons_blind2_position')|float > 70 %}
    mdi:blinds-open
{% else %}
    mdi:blinds
{% endif %}) renders=3>
Traceback (most recent call last):
  File "/usr/src/homeassistant/homeassistant/helpers/template.py", line 2258, in forgiving_float_filter
    return float(value)
           ^^^^^^^^^^^^
ValueError: could not convert string to float: 'unavailable'

During handling of the above exception, another exception occurred:

Traceback (most recent call last):
  File "/usr/src/homeassistant/homeassistant/helpers/template.py", line 604, in async_render
    render_result = _render_with_context(self.template, compiled, **kwargs)
                    ^^^^^^^^^^^^^^^^^^^^^^^^^^^^^^^^^^^^^^^^^^^^^^^^^^^^^^^
  File "/usr/src/homeassistant/homeassistant/helpers/template.py", line 2639, in _render_with_context
    return template.render(**kwargs)
           ^^^^^^^^^^^^^^^^^^^^^^^^^
  File "/usr/local/lib/python3.12/site-packages/jinja2/environment.py", line 1304, in render
    self.environment.handle_exception()
  File "/usr/local/lib/python3.12/site-packages/jinja2/environment.py", line 939, in handle_exception
    raise rewrite_traceback_stack(source=source)
  File "<template>", line 1, in top-level template code
  File "/usr/src/homeassistant/homeassistant/helpers/template.py", line 2261, in forgiving_float_filter
    raise_no_default("float", value)
  File "/usr/src/homeassistant/homeassistant/helpers/template.py", line 1872, in raise_no_default
    raise ValueError(
ValueError: Template error: float got invalid input 'unavailable' when rendering template '{% if states('sensor.sons_blind2_position')|float > 70 %}
    mdi:blinds-open
{% else %}
    mdi:blinds
{% endif %}' but no default was specified

The above exception was the direct cause of the following exception:

Traceback (most recent call last):
  File "/usr/src/homeassistant/homeassistant/helpers/template.py", line 716, in async_render_to_info
    render_info._result = self.async_render(  # noqa: SLF001
                          ^^^^^^^^^^^^^^^^^^^^^^^^^^^^^^^^^^
  File "/usr/src/homeassistant/homeassistant/helpers/template.py", line 606, in async_render
    raise TemplateError(err) from err
homeassistant.exceptions.TemplateError: ValueError: Template error: float got invalid input 'unavailable' when rendering template '{% if states('sensor.sons_blind2_position')|float > 70 %}
    mdi:blinds-open
{% else %}
    mdi:blinds
{% endif %}' but no default was specified
2024-09-19 11:46:25.880 ERROR (MainThread) [homeassistant.components.template.template_entity] TemplateError('ValueError: Template error: int got invalid input 'unavailable' when rendering template '{{(states('sensor.sons_blind2_position')) | int}}' but no default was specified') while processing template 'Template<template=({{(states('sensor.sons_blind2_position')) | int}}) renders=4>' for attribute '_position' in entity 'cover.sons_blind2'
2024-09-19 11:46:25.881 ERROR (MainThread) [homeassistant.components.template.template_entity] TemplateError('ValueError: Template error: float got invalid input 'unavailable' when rendering template '{% if states('sensor.sons_blind2_position')|float > 70 %}
    mdi:blinds-open
{% else %}
    mdi:blinds
{% endif %}' but no default was specified') while processing template 'Template<template=({% if states('sensor.sons_blind2_position')|float > 70 %}
    mdi:blinds-open
{% else %}
    mdi:blinds
{% endif %}) renders=5>' for attribute '_attr_icon' in entity 'cover.sons_blind2'
2024-09-19 11:46:26.113 ERROR (MainThread) [homeassistant.components.automation.corridor_light_automation_2] Error rendering variables: UndefinedError: 'dict object' has no attribute 'entity_id'
2024-09-19 11:47:42.736 ERROR (MainThread) [aiohttp.server] Error handling request
Traceback (most recent call last):
  File "/usr/local/lib/python3.12/site-packages/aiohttp/web_protocol.py", line 350, in data_received
    messages, upgraded, tail = self._request_parser.feed_data(data)
                               ^^^^^^^^^^^^^^^^^^^^^^^^^^^^^^^^^^^^
  File "aiohttp/_http_parser.pyx", line 557, in aiohttp._http_parser.HttpParser.feed_data
aiohttp.http_exceptions.BadStatusLine: 400, message:
  Invalid method encountered:

    b'\x16\x03\x01\x02\x98\x01'
      ^
2024-09-19 11:47:55.128 ERROR (MainThread) [aiohttp.server] Error handling request
Traceback (most recent call last):
  File "/usr/local/lib/python3.12/site-packages/aiohttp/web_protocol.py", line 350, in data_received
    messages, upgraded, tail = self._request_parser.feed_data(data)
                               ^^^^^^^^^^^^^^^^^^^^^^^^^^^^^^^^^^^^
  File "aiohttp/_http_parser.pyx", line 557, in aiohttp._http_parser.HttpParser.feed_data
aiohttp.http_exceptions.BadStatusLine: 400, message:
  Invalid method encountered:

    b'\x16\x03\x01\x02\x98\x01'
      ^
2024-09-19 11:47:55.140 ERROR (MainThread) [aiohttp.server] Error handling request
Traceback (most recent call last):
  File "/usr/local/lib/python3.12/site-packages/aiohttp/web_protocol.py", line 350, in data_received
    messages, upgraded, tail = self._request_parser.feed_data(data)
                               ^^^^^^^^^^^^^^^^^^^^^^^^^^^^^^^^^^^^
  File "aiohttp/_http_parser.pyx", line 557, in aiohttp._http_parser.HttpParser.feed_data
aiohttp.http_exceptions.BadStatusLine: 400, message:
  Invalid method encountered:

    b'\x16\x03\x01\x02\x98\x01'
      ^
2024-09-19 11:50:50.820 ERROR (MainThread) [aiohttp.server] Error handling request
Traceback (most recent call last):
  File "/usr/local/lib/python3.12/site-packages/aiohttp/web_protocol.py", line 350, in data_received
    messages, upgraded, tail = self._request_parser.feed_data(data)
                               ^^^^^^^^^^^^^^^^^^^^^^^^^^^^^^^^^^^^
  File "aiohttp/_http_parser.pyx", line 557, in aiohttp._http_parser.HttpParser.feed_data
aiohttp.http_exceptions.BadStatusLine: 400, message:
  Invalid method encountered:

    b'\x16\x03\x01\x02\x98\x01'
      ^
2024-09-19 12:05:27.937 ERROR (MainThread) [aiohttp.server] Error handling request
Traceback (most recent call last):
  File "/usr/local/lib/python3.12/site-packages/aiohttp/web_protocol.py", line 350, in data_received
    messages, upgraded, tail = self._request_parser.feed_data(data)
                               ^^^^^^^^^^^^^^^^^^^^^^^^^^^^^^^^^^^^
  File "aiohttp/_http_parser.pyx", line 557, in aiohttp._http_parser.HttpParser.feed_data
aiohttp.http_exceptions.BadStatusLine: 400, message:
  Invalid method encountered:

    b'\x16\x03\x01\x02\x98\x01'
      ^
2024-09-19 12:05:27.944 ERROR (MainThread) [aiohttp.server] Error handling request
Traceback (most recent call last):
  File "/usr/local/lib/python3.12/site-packages/aiohttp/web_protocol.py", line 350, in data_received
    messages, upgraded, tail = self._request_parser.feed_data(data)
                               ^^^^^^^^^^^^^^^^^^^^^^^^^^^^^^^^^^^^
  File "aiohttp/_http_parser.pyx", line 557, in aiohttp._http_parser.HttpParser.feed_data
aiohttp.http_exceptions.BadStatusLine: 400, message:
  Invalid method encountered:

    b'\x16\x03\x01\x02\x98\x01'
      ^
2024-09-19 12:06:57.502 ERROR (MainThread) [aiohttp.server] Error handling request
Traceback (most recent call last):
  File "/usr/local/lib/python3.12/site-packages/aiohttp/web_protocol.py", line 350, in data_received
    messages, upgraded, tail = self._request_parser.feed_data(data)
                               ^^^^^^^^^^^^^^^^^^^^^^^^^^^^^^^^^^^^
  File "aiohttp/_http_parser.pyx", line 557, in aiohttp._http_parser.HttpParser.feed_data
aiohttp.http_exceptions.BadStatusLine: 400, message:
  Invalid method encountered:

    b'\x16\x03\x01\x02\x98\x01'
      ^
2024-09-19 12:06:57.508 ERROR (MainThread) [aiohttp.server] Error handling request
Traceback (most recent call last):
  File "/usr/local/lib/python3.12/site-packages/aiohttp/web_protocol.py", line 350, in data_received
    messages, upgraded, tail = self._request_parser.feed_data(data)
                               ^^^^^^^^^^^^^^^^^^^^^^^^^^^^^^^^^^^^
  File "aiohttp/_http_parser.pyx", line 557, in aiohttp._http_parser.HttpParser.feed_data
aiohttp.http_exceptions.BadStatusLine: 400, message:
  Invalid method encountered:

    b'\x16\x03\x01\x02\x98\x01'
      ^
2024-09-19 12:06:57.513 ERROR (MainThread) [aiohttp.server] Error handling request
Traceback (most recent call last):
  File "/usr/local/lib/python3.12/site-packages/aiohttp/web_protocol.py", line 350, in data_received
    messages, upgraded, tail = self._request_parser.feed_data(data)
                               ^^^^^^^^^^^^^^^^^^^^^^^^^^^^^^^^^^^^
  File "aiohttp/_http_parser.pyx", line 557, in aiohttp._http_parser.HttpParser.feed_data
aiohttp.http_exceptions.BadStatusLine: 400, message:
  Invalid method encountered:

    b'\x16\x03\x01\x02\x98\x01'
      ^
2024-09-19 12:07:21.262 ERROR (MainThread) [aiohttp.server] Error handling request
Traceback (most recent call last):
  File "/usr/local/lib/python3.12/site-packages/aiohttp/web_protocol.py", line 350, in data_received
    messages, upgraded, tail = self._request_parser.feed_data(data)
                               ^^^^^^^^^^^^^^^^^^^^^^^^^^^^^^^^^^^^
  File "aiohttp/_http_parser.pyx", line 557, in aiohttp._http_parser.HttpParser.feed_data
aiohttp.http_exceptions.BadStatusLine: 400, message:
  Invalid method encountered:

    b'\x16\x03\x01\x01\x0c\x01'
      ^
2024-09-19 12:07:47.984 ERROR (MainThread) [aiohttp.server] Error handling request
Traceback (most recent call last):
  File "/usr/local/lib/python3.12/site-packages/aiohttp/web_protocol.py", line 350, in data_received
    messages, upgraded, tail = self._request_parser.feed_data(data)
                               ^^^^^^^^^^^^^^^^^^^^^^^^^^^^^^^^^^^^
  File "aiohttp/_http_parser.pyx", line 557, in aiohttp._http_parser.HttpParser.feed_data
aiohttp.http_exceptions.BadStatusLine: 400, message:
  Invalid method encountered:

    b'\x16\x03\x01\x06\xbe\x01'
      ^
2024-09-19 12:07:47.993 ERROR (MainThread) [aiohttp.server] Error handling request
Traceback (most recent call last):
  File "/usr/local/lib/python3.12/site-packages/aiohttp/web_protocol.py", line 350, in data_received
    messages, upgraded, tail = self._request_parser.feed_data(data)
                               ^^^^^^^^^^^^^^^^^^^^^^^^^^^^^^^^^^^^
  File "aiohttp/_http_parser.pyx", line 557, in aiohttp._http_parser.HttpParser.feed_data
aiohttp.http_exceptions.BadStatusLine: 400, message:
  Invalid method encountered:

    b'\x16\x03\x01\x06\xfe\x01'
      ^
2024-09-19 12:07:48.006 ERROR (MainThread) [aiohttp.server] Error handling request
Traceback (most recent call last):
  File "/usr/local/lib/python3.12/site-packages/aiohttp/web_protocol.py", line 350, in data_received
    messages, upgraded, tail = self._request_parser.feed_data(data)
                               ^^^^^^^^^^^^^^^^^^^^^^^^^^^^^^^^^^^^
  File "aiohttp/_http_parser.pyx", line 557, in aiohttp._http_parser.HttpParser.feed_data
aiohttp.http_exceptions.BadStatusLine: 400, message:
  Invalid method encountered:

    b'\x16\x03\x01\x07\x1e\x01'
      ^
2024-09-19 12:07:48.015 ERROR (MainThread) [aiohttp.server] Error handling request
Traceback (most recent call last):
  File "/usr/local/lib/python3.12/site-packages/aiohttp/web_protocol.py", line 350, in data_received
    messages, upgraded, tail = self._request_parser.feed_data(data)
                               ^^^^^^^^^^^^^^^^^^^^^^^^^^^^^^^^^^^^
  File "aiohttp/_http_parser.pyx", line 557, in aiohttp._http_parser.HttpParser.feed_data
aiohttp.http_exceptions.BadStatusLine: 400, message:
  Invalid method encountered:

    b'\x16\x03\x01\x06\xfe\x01'
      ^
2024-09-19 12:07:48.056 ERROR (MainThread) [aiohttp.server] Error handling request
Traceback (most recent call last):
  File "/usr/local/lib/python3.12/site-packages/aiohttp/web_protocol.py", line 350, in data_received
    messages, upgraded, tail = self._request_parser.feed_data(data)
                               ^^^^^^^^^^^^^^^^^^^^^^^^^^^^^^^^^^^^
  File "aiohttp/_http_parser.pyx", line 557, in aiohttp._http_parser.HttpParser.feed_data
aiohttp.http_exceptions.BadStatusLine: 400, message:
  Invalid method encountered:

    b'\x16\x03\x01\x06\xbe\x01'
      ^
2024-09-19 12:07:48.070 ERROR (MainThread) [aiohttp.server] Error handling request
Traceback (most recent call last):
  File "/usr/local/lib/python3.12/site-packages/aiohttp/web_protocol.py", line 350, in data_received
    messages, upgraded, tail = self._request_parser.feed_data(data)
                               ^^^^^^^^^^^^^^^^^^^^^^^^^^^^^^^^^^^^
  File "aiohttp/_http_parser.pyx", line 557, in aiohttp._http_parser.HttpParser.feed_data
aiohttp.http_exceptions.BadStatusLine: 400, message:
  Invalid method encountered:

    b'\x16\x03\x01\x06\xbe\x01'
      ^
2024-09-19 12:07:48.075 ERROR (MainThread) [aiohttp.server] Error handling request
Traceback (most recent call last):
  File "/usr/local/lib/python3.12/site-packages/aiohttp/web_protocol.py", line 350, in data_received
    messages, upgraded, tail = self._request_parser.feed_data(data)
                               ^^^^^^^^^^^^^^^^^^^^^^^^^^^^^^^^^^^^
  File "aiohttp/_http_parser.pyx", line 557, in aiohttp._http_parser.HttpParser.feed_data
aiohttp.http_exceptions.BadStatusLine: 400, message:
  Invalid method encountered:

    b'\x16\x03\x01\x06\xfe\x01'
      ^
2024-09-19 12:07:48.080 ERROR (MainThread) [aiohttp.server] Error handling request
Traceback (most recent call last):
  File "/usr/local/lib/python3.12/site-packages/aiohttp/web_protocol.py", line 350, in data_received
    messages, upgraded, tail = self._request_parser.feed_data(data)
                               ^^^^^^^^^^^^^^^^^^^^^^^^^^^^^^^^^^^^
  File "aiohttp/_http_parser.pyx", line 557, in aiohttp._http_parser.HttpParser.feed_data
aiohttp.http_exceptions.BadStatusLine: 400, message:
  Invalid method encountered:

    b'\x16\x03\x01\x07\x1e\x01'
      ^
2024-09-19 12:07:48.085 ERROR (MainThread) [aiohttp.server] Error handling request
Traceback (most recent call last):
  File "/usr/local/lib/python3.12/site-packages/aiohttp/web_protocol.py", line 350, in data_received
    messages, upgraded, tail = self._request_parser.feed_data(data)
                               ^^^^^^^^^^^^^^^^^^^^^^^^^^^^^^^^^^^^
  File "aiohttp/_http_parser.pyx", line 557, in aiohttp._http_parser.HttpParser.feed_data
aiohttp.http_exceptions.BadStatusLine: 400, message:
  Invalid method encountered:

    b'\x16\x03\x01\x06\xde\x01'
      ^
2024-09-19 12:07:48.089 ERROR (MainThread) [aiohttp.server] Error handling request
Traceback (most recent call last):
  File "/usr/local/lib/python3.12/site-packages/aiohttp/web_protocol.py", line 350, in data_received
    messages, upgraded, tail = self._request_parser.feed_data(data)
                               ^^^^^^^^^^^^^^^^^^^^^^^^^^^^^^^^^^^^
  File "aiohttp/_http_parser.pyx", line 557, in aiohttp._http_parser.HttpParser.feed_data
aiohttp.http_exceptions.BadStatusLine: 400, message:
  Invalid method encountered:

    b'\x16\x03\x01\x06\xbe\x01'
      ^
2024-09-19 12:07:48.105 ERROR (MainThread) [aiohttp.server] Error handling request
Traceback (most recent call last):
  File "/usr/local/lib/python3.12/site-packages/aiohttp/web_protocol.py", line 350, in data_received
    messages, upgraded, tail = self._request_parser.feed_data(data)
                               ^^^^^^^^^^^^^^^^^^^^^^^^^^^^^^^^^^^^
  File "aiohttp/_http_parser.pyx", line 557, in aiohttp._http_parser.HttpParser.feed_data
aiohttp.http_exceptions.BadStatusLine: 400, message:
  Invalid method encountered:

    b'\x16\x03\x01\x06\xbe\x01'
      ^
2024-09-19 12:07:48.110 ERROR (MainThread) [aiohttp.server] Error handling request
Traceback (most recent call last):
  File "/usr/local/lib/python3.12/site-packages/aiohttp/web_protocol.py", line 350, in data_received
    messages, upgraded, tail = self._request_parser.feed_data(data)
                               ^^^^^^^^^^^^^^^^^^^^^^^^^^^^^^^^^^^^
  File "aiohttp/_http_parser.pyx", line 557, in aiohttp._http_parser.HttpParser.feed_data
aiohttp.http_exceptions.BadStatusLine: 400, message:
  Invalid method encountered:

    b'\x16\x03\x01\x06\xbe\x01'
      ^
2024-09-19 12:07:48.114 ERROR (MainThread) [aiohttp.server] Error handling request
Traceback (most recent call last):
  File "/usr/local/lib/python3.12/site-packages/aiohttp/web_protocol.py", line 350, in data_received
    messages, upgraded, tail = self._request_parser.feed_data(data)
                               ^^^^^^^^^^^^^^^^^^^^^^^^^^^^^^^^^^^^
  File "aiohttp/_http_parser.pyx", line 557, in aiohttp._http_parser.HttpParser.feed_data
aiohttp.http_exceptions.BadStatusLine: 400, message:
  Invalid method encountered:

    b'\x16\x03\x01\x07\x1e\x01'
      ^
2024-09-19 12:07:48.120 ERROR (MainThread) [aiohttp.server] Error handling request
Traceback (most recent call last):
  File "/usr/local/lib/python3.12/site-packages/aiohttp/web_protocol.py", line 350, in data_received
    messages, upgraded, tail = self._request_parser.feed_data(data)
                               ^^^^^^^^^^^^^^^^^^^^^^^^^^^^^^^^^^^^
  File "aiohttp/_http_parser.pyx", line 557, in aiohttp._http_parser.HttpParser.feed_data
aiohttp.http_exceptions.BadStatusLine: 400, message:
  Invalid method encountered:

    b'\x16\x03\x01\x06\xbe\x01'
      ^
2024-09-19 12:07:48.129 ERROR (MainThread) [aiohttp.server] Error handling request
Traceback (most recent call last):
  File "/usr/local/lib/python3.12/site-packages/aiohttp/web_protocol.py", line 350, in data_received
    messages, upgraded, tail = self._request_parser.feed_data(data)
                               ^^^^^^^^^^^^^^^^^^^^^^^^^^^^^^^^^^^^
  File "aiohttp/_http_parser.pyx", line 557, in aiohttp._http_parser.HttpParser.feed_data
aiohttp.http_exceptions.BadStatusLine: 400, message:
  Invalid method encountered:

    b'\x16\x03\x01\x06\xde\x01'
      ^
2024-09-19 12:07:48.147 ERROR (MainThread) [aiohttp.server] Error handling request
Traceback (most recent call last):
  File "/usr/local/lib/python3.12/site-packages/aiohttp/web_protocol.py", line 350, in data_received
    messages, upgraded, tail = self._request_parser.feed_data(data)
                               ^^^^^^^^^^^^^^^^^^^^^^^^^^^^^^^^^^^^
  File "aiohttp/_http_parser.pyx", line 557, in aiohttp._http_parser.HttpParser.feed_data
aiohttp.http_exceptions.BadStatusLine: 400, message:
  Invalid method encountered:

    b'\x16\x03\x01\x06\xde\x01'
      ^
2024-09-19 12:07:48.152 ERROR (MainThread) [aiohttp.server] Error handling request
Traceback (most recent call last):
  File "/usr/local/lib/python3.12/site-packages/aiohttp/web_protocol.py", line 350, in data_received
    messages, upgraded, tail = self._request_parser.feed_data(data)
                               ^^^^^^^^^^^^^^^^^^^^^^^^^^^^^^^^^^^^
  File "aiohttp/_http_parser.pyx", line 557, in aiohttp._http_parser.HttpParser.feed_data
aiohttp.http_exceptions.BadStatusLine: 400, message:
  Invalid method encountered:

    b'\x16\x03\x01\x06\xde\x01'
      ^
2024-09-19 12:07:48.157 ERROR (MainThread) [aiohttp.server] Error handling request
Traceback (most recent call last):
  File "/usr/local/lib/python3.12/site-packages/aiohttp/web_protocol.py", line 350, in data_received
    messages, upgraded, tail = self._request_parser.feed_data(data)
                               ^^^^^^^^^^^^^^^^^^^^^^^^^^^^^^^^^^^^
  File "aiohttp/_http_parser.pyx", line 557, in aiohttp._http_parser.HttpParser.feed_data
aiohttp.http_exceptions.BadStatusLine: 400, message:
  Invalid method encountered:

    b'\x16\x03\x01\x06\xbe\x01'
      ^
2024-09-19 12:07:48.167 ERROR (MainThread) [aiohttp.server] Error handling request
Traceback (most recent call last):
  File "/usr/local/lib/python3.12/site-packages/aiohttp/web_protocol.py", line 350, in data_received
    messages, upgraded, tail = self._request_parser.feed_data(data)
                               ^^^^^^^^^^^^^^^^^^^^^^^^^^^^^^^^^^^^
  File "aiohttp/_http_parser.pyx", line 557, in aiohttp._http_parser.HttpParser.feed_data
aiohttp.http_exceptions.BadStatusLine: 400, message:
  Invalid method encountered:

    b'\x16\x03\x01\x07\x1e\x01'
      ^
2024-09-19 12:07:48.176 ERROR (MainThread) [aiohttp.server] Error handling request
Traceback (most recent call last):
  File "/usr/local/lib/python3.12/site-packages/aiohttp/web_protocol.py", line 350, in data_received
    messages, upgraded, tail = self._request_parser.feed_data(data)
                               ^^^^^^^^^^^^^^^^^^^^^^^^^^^^^^^^^^^^
  File "aiohttp/_http_parser.pyx", line 557, in aiohttp._http_parser.HttpParser.feed_data
aiohttp.http_exceptions.BadStatusLine: 400, message:
  Invalid method encountered:

    b'\x16\x03\x01\x06\xde\x01'
      ^
2024-09-19 12:07:48.179 ERROR (MainThread) [aiohttp.server] Error handling request
Traceback (most recent call last):
  File "/usr/local/lib/python3.12/site-packages/aiohttp/web_protocol.py", line 350, in data_received
    messages, upgraded, tail = self._request_parser.feed_data(data)
                               ^^^^^^^^^^^^^^^^^^^^^^^^^^^^^^^^^^^^
  File "aiohttp/_http_parser.pyx", line 557, in aiohttp._http_parser.HttpParser.feed_data
aiohttp.http_exceptions.BadStatusLine: 400, message:
  Invalid method encountered:

    b'\x16\x03\x01\x06\xbe\x01'
      ^
2024-09-19 12:07:48.192 ERROR (MainThread) [aiohttp.server] Error handling request
Traceback (most recent call last):
  File "/usr/local/lib/python3.12/site-packages/aiohttp/web_protocol.py", line 350, in data_received
    messages, upgraded, tail = self._request_parser.feed_data(data)
                               ^^^^^^^^^^^^^^^^^^^^^^^^^^^^^^^^^^^^
  File "aiohttp/_http_parser.pyx", line 557, in aiohttp._http_parser.HttpParser.feed_data
aiohttp.http_exceptions.BadStatusLine: 400, message:
  Invalid method encountered:

    b'\x16\x03\x01\x06\xbe\x01'
      ^
2024-09-19 12:07:48.197 ERROR (MainThread) [aiohttp.server] Error handling request
Traceback (most recent call last):
  File "/usr/local/lib/python3.12/site-packages/aiohttp/web_protocol.py", line 350, in data_received
    messages, upgraded, tail = self._request_parser.feed_data(data)
                               ^^^^^^^^^^^^^^^^^^^^^^^^^^^^^^^^^^^^
  File "aiohttp/_http_parser.pyx", line 557, in aiohttp._http_parser.HttpParser.feed_data
aiohttp.http_exceptions.BadStatusLine: 400, message:
  Invalid method encountered:

    b'\x16\x03\x01\x06\xfe\x01'
      ^
2024-09-19 12:07:48.205 ERROR (MainThread) [aiohttp.server] Error handling request
Traceback (most recent call last):
  File "/usr/local/lib/python3.12/site-packages/aiohttp/web_protocol.py", line 350, in data_received
    messages, upgraded, tail = self._request_parser.feed_data(data)
                               ^^^^^^^^^^^^^^^^^^^^^^^^^^^^^^^^^^^^
  File "aiohttp/_http_parser.pyx", line 557, in aiohttp._http_parser.HttpParser.feed_data
aiohttp.http_exceptions.BadStatusLine: 400, message:
  Invalid method encountered:

    b'\x16\x03\x01\x06\xde\x01'
      ^
2024-09-19 12:07:48.210 ERROR (MainThread) [aiohttp.server] Error handling request
Traceback (most recent call last):
  File "/usr/local/lib/python3.12/site-packages/aiohttp/web_protocol.py", line 350, in data_received
    messages, upgraded, tail = self._request_parser.feed_data(data)
                               ^^^^^^^^^^^^^^^^^^^^^^^^^^^^^^^^^^^^
  File "aiohttp/_http_parser.pyx", line 557, in aiohttp._http_parser.HttpParser.feed_data
aiohttp.http_exceptions.BadStatusLine: 400, message:
  Invalid method encountered:

    b'\x16\x03\x01\x07\x1e\x01'
      ^
2024-09-19 12:07:48.221 ERROR (MainThread) [aiohttp.server] Error handling request
Traceback (most recent call last):
  File "/usr/local/lib/python3.12/site-packages/aiohttp/web_protocol.py", line 350, in data_received
    messages, upgraded, tail = self._request_parser.feed_data(data)
                               ^^^^^^^^^^^^^^^^^^^^^^^^^^^^^^^^^^^^
  File "aiohttp/_http_parser.pyx", line 557, in aiohttp._http_parser.HttpParser.feed_data
aiohttp.http_exceptions.BadStatusLine: 400, message:
  Invalid method encountered:

    b'\x16\x03\x01\x06\xbe\x01'
      ^
2024-09-19 12:07:48.226 ERROR (MainThread) [aiohttp.server] Error handling request
Traceback (most recent call last):
  File "/usr/local/lib/python3.12/site-packages/aiohttp/web_protocol.py", line 350, in data_received
    messages, upgraded, tail = self._request_parser.feed_data(data)
                               ^^^^^^^^^^^^^^^^^^^^^^^^^^^^^^^^^^^^
  File "aiohttp/_http_parser.pyx", line 557, in aiohttp._http_parser.HttpParser.feed_data
aiohttp.http_exceptions.BadStatusLine: 400, message:
  Invalid method encountered:

    b'\x16\x03\x01\x06\xde\x01'
      ^
2024-09-19 12:07:48.236 ERROR (MainThread) [aiohttp.server] Error handling request
Traceback (most recent call last):
  File "/usr/local/lib/python3.12/site-packages/aiohttp/web_protocol.py", line 350, in data_received
    messages, upgraded, tail = self._request_parser.feed_data(data)
                               ^^^^^^^^^^^^^^^^^^^^^^^^^^^^^^^^^^^^
  File "aiohttp/_http_parser.pyx", line 557, in aiohttp._http_parser.HttpParser.feed_data
aiohttp.http_exceptions.BadStatusLine: 400, message:
  Invalid method encountered:

    b'\x16\x03\x01\x06\xde\x01'
      ^
2024-09-19 12:07:48.241 ERROR (MainThread) [aiohttp.server] Error handling request
Traceback (most recent call last):
  File "/usr/local/lib/python3.12/site-packages/aiohttp/web_protocol.py", line 350, in data_received
    messages, upgraded, tail = self._request_parser.feed_data(data)
                               ^^^^^^^^^^^^^^^^^^^^^^^^^^^^^^^^^^^^
  File "aiohttp/_http_parser.pyx", line 557, in aiohttp._http_parser.HttpParser.feed_data
aiohttp.http_exceptions.BadStatusLine: 400, message:
  Invalid method encountered:

    b'\x16\x03\x01\x07\x1e\x01'
      ^
2024-09-19 12:07:48.252 ERROR (MainThread) [aiohttp.server] Error handling request
Traceback (most recent call last):
  File "/usr/local/lib/python3.12/site-packages/aiohttp/web_protocol.py", line 350, in data_received
    messages, upgraded, tail = self._request_parser.feed_data(data)
                               ^^^^^^^^^^^^^^^^^^^^^^^^^^^^^^^^^^^^
  File "aiohttp/_http_parser.pyx", line 557, in aiohttp._http_parser.HttpParser.feed_data
aiohttp.http_exceptions.BadStatusLine: 400, message:
  Invalid method encountered:

    b'\x16\x03\x01\x07\x1e\x01'
      ^
2024-09-19 12:07:48.257 ERROR (MainThread) [aiohttp.server] Error handling request
Traceback (most recent call last):
  File "/usr/local/lib/python3.12/site-packages/aiohttp/web_protocol.py", line 350, in data_received
    messages, upgraded, tail = self._request_parser.feed_data(data)
                               ^^^^^^^^^^^^^^^^^^^^^^^^^^^^^^^^^^^^
  File "aiohttp/_http_parser.pyx", line 557, in aiohttp._http_parser.HttpParser.feed_data
aiohttp.http_exceptions.BadStatusLine: 400, message:
  Invalid method encountered:

    b'\x16\x03\x01\x07\x12\x01'
      ^
2024-09-19 12:07:48.263 ERROR (MainThread) [aiohttp.server] Error handling request
Traceback (most recent call last):
  File "/usr/local/lib/python3.12/site-packages/aiohttp/web_protocol.py", line 350, in data_received
    messages, upgraded, tail = self._request_parser.feed_data(data)
                               ^^^^^^^^^^^^^^^^^^^^^^^^^^^^^^^^^^^^
  File "aiohttp/_http_parser.pyx", line 557, in aiohttp._http_parser.HttpParser.feed_data
aiohttp.http_exceptions.BadStatusLine: 400, message:
  Invalid method encountered:

    b'\x16\x03\x01\x06\xbe\x01'
      ^
2024-09-19 12:07:48.274 ERROR (MainThread) [aiohttp.server] Error handling request
Traceback (most recent call last):
  File "/usr/local/lib/python3.12/site-packages/aiohttp/web_protocol.py", line 350, in data_received
    messages, upgraded, tail = self._request_parser.feed_data(data)
                               ^^^^^^^^^^^^^^^^^^^^^^^^^^^^^^^^^^^^
  File "aiohttp/_http_parser.pyx", line 557, in aiohttp._http_parser.HttpParser.feed_data
aiohttp.http_exceptions.BadStatusLine: 400, message:
  Invalid method encountered:

    b'\x16\x03\x01\x06\xfe\x01'
      ^
2024-09-19 12:07:48.280 ERROR (MainThread) [aiohttp.server] Error handling request
Traceback (most recent call last):
  File "/usr/local/lib/python3.12/site-packages/aiohttp/web_protocol.py", line 350, in data_received
    messages, upgraded, tail = self._request_parser.feed_data(data)
                               ^^^^^^^^^^^^^^^^^^^^^^^^^^^^^^^^^^^^
  File "aiohttp/_http_parser.pyx", line 557, in aiohttp._http_parser.HttpParser.feed_data
aiohttp.http_exceptions.BadStatusLine: 400, message:
  Invalid method encountered:

    b'\x16\x03\x01\x06\xfe\x01'
      ^
2024-09-19 12:07:48.290 ERROR (MainThread) [aiohttp.server] Error handling request
Traceback (most recent call last):
  File "/usr/local/lib/python3.12/site-packages/aiohttp/web_protocol.py", line 350, in data_received
    messages, upgraded, tail = self._request_parser.feed_data(data)
                               ^^^^^^^^^^^^^^^^^^^^^^^^^^^^^^^^^^^^
  File "aiohttp/_http_parser.pyx", line 557, in aiohttp._http_parser.HttpParser.feed_data
aiohttp.http_exceptions.BadStatusLine: 400, message:
  Invalid method encountered:

    b'\x16\x03\x01\x06\xfe\x01'
      ^
2024-09-19 12:07:48.294 ERROR (MainThread) [aiohttp.server] Error handling request
Traceback (most recent call last):
  File "/usr/local/lib/python3.12/site-packages/aiohttp/web_protocol.py", line 350, in data_received
    messages, upgraded, tail = self._request_parser.feed_data(data)
                               ^^^^^^^^^^^^^^^^^^^^^^^^^^^^^^^^^^^^
  File "aiohttp/_http_parser.pyx", line 557, in aiohttp._http_parser.HttpParser.feed_data
aiohttp.http_exceptions.BadStatusLine: 400, message:
  Invalid method encountered:

    b'\x16\x03\x01\x06\xf2\x01'
      ^
2024-09-19 12:07:48.441 ERROR (MainThread) [aiohttp.server] Error handling request
Traceback (most recent call last):
  File "/usr/local/lib/python3.12/site-packages/aiohttp/web_protocol.py", line 350, in data_received
    messages, upgraded, tail = self._request_parser.feed_data(data)
                               ^^^^^^^^^^^^^^^^^^^^^^^^^^^^^^^^^^^^
  File "aiohttp/_http_parser.pyx", line 557, in aiohttp._http_parser.HttpParser.feed_data
aiohttp.http_exceptions.BadStatusLine: 400, message:
  Invalid method encountered:

    b'\x16\x03\x01\x06\xbe\x01'
      ^
2024-09-19 12:07:48.460 ERROR (MainThread) [aiohttp.server] Error handling request
Traceback (most recent call last):
  File "/usr/local/lib/python3.12/site-packages/aiohttp/web_protocol.py", line 350, in data_received
    messages, upgraded, tail = self._request_parser.feed_data(data)
                               ^^^^^^^^^^^^^^^^^^^^^^^^^^^^^^^^^^^^
  File "aiohttp/_http_parser.pyx", line 557, in aiohttp._http_parser.HttpParser.feed_data
aiohttp.http_exceptions.BadStatusLine: 400, message:
  Invalid method encountered:

    b'\x16\x03\x01\x06\xde\x01'
      ^
2024-09-19 12:07:48.492 ERROR (MainThread) [aiohttp.server] Error handling request
Traceback (most recent call last):
  File "/usr/local/lib/python3.12/site-packages/aiohttp/web_protocol.py", line 350, in data_received
    messages, upgraded, tail = self._request_parser.feed_data(data)
                               ^^^^^^^^^^^^^^^^^^^^^^^^^^^^^^^^^^^^
  File "aiohttp/_http_parser.pyx", line 557, in aiohttp._http_parser.HttpParser.feed_data
aiohttp.http_exceptions.BadStatusLine: 400, message:
  Invalid method encountered:

    b'\x16\x03\x01\x06\xfe\x01'
      ^
2024-09-19 12:07:48.519 ERROR (MainThread) [aiohttp.server] Error handling request
Traceback (most recent call last):
  File "/usr/local/lib/python3.12/site-packages/aiohttp/web_protocol.py", line 350, in data_received
    messages, upgraded, tail = self._request_parser.feed_data(data)
                               ^^^^^^^^^^^^^^^^^^^^^^^^^^^^^^^^^^^^
  File "aiohttp/_http_parser.pyx", line 557, in aiohttp._http_parser.HttpParser.feed_data
aiohttp.http_exceptions.BadStatusLine: 400, message:
  Invalid method encountered:

    b'\x16\x03\x01\x06\xbe\x01'
      ^
2024-09-19 12:07:48.637 ERROR (MainThread) [aiohttp.server] Error handling request
Traceback (most recent call last):
  File "/usr/local/lib/python3.12/site-packages/aiohttp/web_protocol.py", line 350, in data_received
    messages, upgraded, tail = self._request_parser.feed_data(data)
                               ^^^^^^^^^^^^^^^^^^^^^^^^^^^^^^^^^^^^
  File "aiohttp/_http_parser.pyx", line 557, in aiohttp._http_parser.HttpParser.feed_data
aiohttp.http_exceptions.BadStatusLine: 400, message:
  Invalid method encountered:

    b'\x16\x03\x01\x06\xde\x01'
      ^
2024-09-19 12:07:48.661 ERROR (MainThread) [aiohttp.server] Error handling request
Traceback (most recent call last):
  File "/usr/local/lib/python3.12/site-packages/aiohttp/web_protocol.py", line 350, in data_received
    messages, upgraded, tail = self._request_parser.feed_data(data)
                               ^^^^^^^^^^^^^^^^^^^^^^^^^^^^^^^^^^^^
  File "aiohttp/_http_parser.pyx", line 557, in aiohttp._http_parser.HttpParser.feed_data
aiohttp.http_exceptions.BadStatusLine: 400, message:
  Invalid method encountered:

    b'\x16\x03\x01\x06\xfe\x01'
      ^
2024-09-19 12:07:50.226 ERROR (MainThread) [aiohttp.server] Error handling request
Traceback (most recent call last):
  File "/usr/local/lib/python3.12/site-packages/aiohttp/web_protocol.py", line 350, in data_received
    messages, upgraded, tail = self._request_parser.feed_data(data)
                               ^^^^^^^^^^^^^^^^^^^^^^^^^^^^^^^^^^^^
  File "aiohttp/_http_parser.pyx", line 557, in aiohttp._http_parser.HttpParser.feed_data
aiohttp.http_exceptions.BadStatusLine: 400, message:
  Invalid method encountered:

    b'\x16\x03\x01\x06\xde\x01'
      ^
2024-09-19 12:07:50.250 ERROR (MainThread) [aiohttp.server] Error handling request
Traceback (most recent call last):
  File "/usr/local/lib/python3.12/site-packages/aiohttp/web_protocol.py", line 350, in data_received
    messages, upgraded, tail = self._request_parser.feed_data(data)
                               ^^^^^^^^^^^^^^^^^^^^^^^^^^^^^^^^^^^^
  File "aiohttp/_http_parser.pyx", line 557, in aiohttp._http_parser.HttpParser.feed_data
aiohttp.http_exceptions.BadStatusLine: 400, message:
  Invalid method encountered:

    b'\x16\x03\x01\x07\x1e\x01'
      ^
2024-09-19 12:07:52.217 ERROR (MainThread) [aiohttp.server] Error handling request
Traceback (most recent call last):
  File "/usr/local/lib/python3.12/site-packages/aiohttp/web_protocol.py", line 350, in data_received
    messages, upgraded, tail = self._request_parser.feed_data(data)
                               ^^^^^^^^^^^^^^^^^^^^^^^^^^^^^^^^^^^^
  File "aiohttp/_http_parser.pyx", line 557, in aiohttp._http_parser.HttpParser.feed_data
aiohttp.http_exceptions.BadStatusLine: 400, message:
  Invalid method encountered:

    b'\x16\x03\x01\x028\x01'
      ^
2024-09-19 12:07:52.689 ERROR (MainThread) [aiohttp.server] Error handling request
Traceback (most recent call last):
  File "/usr/local/lib/python3.12/site-packages/aiohttp/web_protocol.py", line 350, in data_received
    messages, upgraded, tail = self._request_parser.feed_data(data)
                               ^^^^^^^^^^^^^^^^^^^^^^^^^^^^^^^^^^^^
  File "aiohttp/_http_parser.pyx", line 557, in aiohttp._http_parser.HttpParser.feed_data
aiohttp.http_exceptions.BadStatusLine: 400, message:
  Invalid method encountered:

    b'\x16\x03\x01\x02X\x01'
      ^
2024-09-19 12:07:53.150 ERROR (MainThread) [aiohttp.server] Error handling request
Traceback (most recent call last):
  File "/usr/local/lib/python3.12/site-packages/aiohttp/web_protocol.py", line 350, in data_received
    messages, upgraded, tail = self._request_parser.feed_data(data)
                               ^^^^^^^^^^^^^^^^^^^^^^^^^^^^^^^^^^^^
  File "aiohttp/_http_parser.pyx", line 557, in aiohttp._http_parser.HttpParser.feed_data
aiohttp.http_exceptions.BadStatusLine: 400, message:
  Invalid method encountered:

    b'\x16\x03\x01\x06\xde\x01'
      ^
2024-09-19 12:07:53.158 ERROR (MainThread) [aiohttp.server] Error handling request
Traceback (most recent call last):
  File "/usr/local/lib/python3.12/site-packages/aiohttp/web_protocol.py", line 350, in data_received
    messages, upgraded, tail = self._request_parser.feed_data(data)
                               ^^^^^^^^^^^^^^^^^^^^^^^^^^^^^^^^^^^^
  File "aiohttp/_http_parser.pyx", line 557, in aiohttp._http_parser.HttpParser.feed_data
aiohttp.http_exceptions.BadStatusLine: 400, message:
  Invalid method encountered:

    b'\x16\x03\x01\x07\x1e\x01'
      ^
2024-09-19 12:07:53.170 ERROR (MainThread) [aiohttp.server] Error handling request
Traceback (most recent call last):
  File "/usr/local/lib/python3.12/site-packages/aiohttp/web_protocol.py", line 350, in data_received
    messages, upgraded, tail = self._request_parser.feed_data(data)
                               ^^^^^^^^^^^^^^^^^^^^^^^^^^^^^^^^^^^^
  File "aiohttp/_http_parser.pyx", line 557, in aiohttp._http_parser.HttpParser.feed_data
aiohttp.http_exceptions.BadStatusLine: 400, message:
  Invalid method encountered:

    b'\x16\x03\x01\x06\xde\x01'
      ^
2024-09-19 12:07:53.181 ERROR (MainThread) [aiohttp.server] Error handling request
Traceback (most recent call last):
  File "/usr/local/lib/python3.12/site-packages/aiohttp/web_protocol.py", line 350, in data_received
    messages, upgraded, tail = self._request_parser.feed_data(data)
                               ^^^^^^^^^^^^^^^^^^^^^^^^^^^^^^^^^^^^
  File "aiohttp/_http_parser.pyx", line 557, in aiohttp._http_parser.HttpParser.feed_data
aiohttp.http_exceptions.BadStatusLine: 400, message:
  Invalid method encountered:

    b'\x16\x03\x01\x07\x1e\x01'
      ^
2024-09-19 12:07:53.388 ERROR (MainThread) [aiohttp.server] Error handling request
Traceback (most recent call last):
  File "/usr/local/lib/python3.12/site-packages/aiohttp/web_protocol.py", line 350, in data_received
    messages, upgraded, tail = self._request_parser.feed_data(data)
                               ^^^^^^^^^^^^^^^^^^^^^^^^^^^^^^^^^^^^
  File "aiohttp/_http_parser.pyx", line 557, in aiohttp._http_parser.HttpParser.feed_data
aiohttp.http_exceptions.BadStatusLine: 400, message:
  Invalid method encountered:

    b'\x16\x03\x01\x06\xfe\x01'
      ^
2024-09-19 12:07:53.398 ERROR (MainThread) [aiohttp.server] Error handling request
Traceback (most recent call last):
  File "/usr/local/lib/python3.12/site-packages/aiohttp/web_protocol.py", line 350, in data_received
    messages, upgraded, tail = self._request_parser.feed_data(data)
                               ^^^^^^^^^^^^^^^^^^^^^^^^^^^^^^^^^^^^
  File "aiohttp/_http_parser.pyx", line 557, in aiohttp._http_parser.HttpParser.feed_data
aiohttp.http_exceptions.BadStatusLine: 400, message:
  Invalid method encountered:

    b'\x16\x03\x01\x07\x1e\x01'
      ^
2024-09-19 12:07:53.403 ERROR (MainThread) [aiohttp.server] Error handling request
Traceback (most recent call last):
  File "/usr/local/lib/python3.12/site-packages/aiohttp/web_protocol.py", line 350, in data_received
    messages, upgraded, tail = self._request_parser.feed_data(data)
                               ^^^^^^^^^^^^^^^^^^^^^^^^^^^^^^^^^^^^
  File "aiohttp/_http_parser.pyx", line 557, in aiohttp._http_parser.HttpParser.feed_data
aiohttp.http_exceptions.BadStatusLine: 400, message:
  Invalid method encountered:

    b'\x16\x03\x01\x06\xde\x01'
      ^
2024-09-19 12:07:53.415 ERROR (MainThread) [aiohttp.server] Error handling request
Traceback (most recent call last):
  File "/usr/local/lib/python3.12/site-packages/aiohttp/web_protocol.py", line 350, in data_received
    messages, upgraded, tail = self._request_parser.feed_data(data)
                               ^^^^^^^^^^^^^^^^^^^^^^^^^^^^^^^^^^^^
  File "aiohttp/_http_parser.pyx", line 557, in aiohttp._http_parser.HttpParser.feed_data
aiohttp.http_exceptions.BadStatusLine: 400, message:
  Invalid method encountered:

    b'\x16\x03\x01\x06\xfe\x01'
      ^
2024-09-19 12:07:53.419 ERROR (MainThread) [aiohttp.server] Error handling request
Traceback (most recent call last):
  File "/usr/local/lib/python3.12/site-packages/aiohttp/web_protocol.py", line 350, in data_received
    messages, upgraded, tail = self._request_parser.feed_data(data)
                               ^^^^^^^^^^^^^^^^^^^^^^^^^^^^^^^^^^^^
  File "aiohttp/_http_parser.pyx", line 557, in aiohttp._http_parser.HttpParser.feed_data
aiohttp.http_exceptions.BadStatusLine: 400, message:
  Invalid method encountered:

    b'\x16\x03\x01\x06\xde\x01'
      ^
2024-09-19 12:07:53.426 ERROR (MainThread) [aiohttp.server] Error handling request
Traceback (most recent call last):
  File "/usr/local/lib/python3.12/site-packages/aiohttp/web_protocol.py", line 350, in data_received
    messages, upgraded, tail = self._request_parser.feed_data(data)
                               ^^^^^^^^^^^^^^^^^^^^^^^^^^^^^^^^^^^^
  File "aiohttp/_http_parser.pyx", line 557, in aiohttp._http_parser.HttpParser.feed_data
aiohttp.http_exceptions.BadStatusLine: 400, message:
  Invalid method encountered:

    b'\x16\x03\x01\x07\x1e\x01'
      ^
2024-09-19 12:07:53.439 ERROR (MainThread) [aiohttp.server] Error handling request
Traceback (most recent call last):
  File "/usr/local/lib/python3.12/site-packages/aiohttp/web_protocol.py", line 350, in data_received
    messages, upgraded, tail = self._request_parser.feed_data(data)
                               ^^^^^^^^^^^^^^^^^^^^^^^^^^^^^^^^^^^^
  File "aiohttp/_http_parser.pyx", line 557, in aiohttp._http_parser.HttpParser.feed_data
aiohttp.http_exceptions.BadStatusLine: 400, message:
  Invalid method encountered:

    b'\x16\x03\x01\x07\x1e\x01'
      ^
2024-09-19 12:07:53.444 ERROR (MainThread) [aiohttp.server] Error handling request
Traceback (most recent call last):
  File "/usr/local/lib/python3.12/site-packages/aiohttp/web_protocol.py", line 350, in data_received
    messages, upgraded, tail = self._request_parser.feed_data(data)
                               ^^^^^^^^^^^^^^^^^^^^^^^^^^^^^^^^^^^^
  File "aiohttp/_http_parser.pyx", line 557, in aiohttp._http_parser.HttpParser.feed_data
aiohttp.http_exceptions.BadStatusLine: 400, message:
  Invalid method encountered:

    b'\x16\x03\x01\x06\xd2\x01'
      ^
2024-09-19 12:07:53.448 ERROR (MainThread) [aiohttp.server] Error handling request
Traceback (most recent call last):
  File "/usr/local/lib/python3.12/site-packages/aiohttp/web_protocol.py", line 350, in data_received
    messages, upgraded, tail = self._request_parser.feed_data(data)
                               ^^^^^^^^^^^^^^^^^^^^^^^^^^^^^^^^^^^^
  File "aiohttp/_http_parser.pyx", line 557, in aiohttp._http_parser.HttpParser.feed_data
aiohttp.http_exceptions.BadStatusLine: 400, message:
  Invalid method encountered:

    b'\x16\x03\x01\x07\x1e\x01'
      ^
2024-09-19 12:07:53.459 ERROR (MainThread) [aiohttp.server] Error handling request
Traceback (most recent call last):
  File "/usr/local/lib/python3.12/site-packages/aiohttp/web_protocol.py", line 350, in data_received
    messages, upgraded, tail = self._request_parser.feed_data(data)
                               ^^^^^^^^^^^^^^^^^^^^^^^^^^^^^^^^^^^^
  File "aiohttp/_http_parser.pyx", line 557, in aiohttp._http_parser.HttpParser.feed_data
aiohttp.http_exceptions.BadStatusLine: 400, message:
  Invalid method encountered:

    b'\x16\x03\x01\x06\xfe\x01'
      ^
2024-09-19 12:07:53.465 ERROR (MainThread) [aiohttp.server] Error handling request
Traceback (most recent call last):
  File "/usr/local/lib/python3.12/site-packages/aiohttp/web_protocol.py", line 350, in data_received
    messages, upgraded, tail = self._request_parser.feed_data(data)
                               ^^^^^^^^^^^^^^^^^^^^^^^^^^^^^^^^^^^^
  File "aiohttp/_http_parser.pyx", line 557, in aiohttp._http_parser.HttpParser.feed_data
aiohttp.http_exceptions.BadStatusLine: 400, message:
  Invalid method encountered:

    b'\x16\x03\x01\x06\xbe\x01'
      ^
2024-09-19 12:07:53.476 ERROR (MainThread) [aiohttp.server] Error handling request
Traceback (most recent call last):
  File "/usr/local/lib/python3.12/site-packages/aiohttp/web_protocol.py", line 350, in data_received
    messages, upgraded, tail = self._request_parser.feed_data(data)
                               ^^^^^^^^^^^^^^^^^^^^^^^^^^^^^^^^^^^^
  File "aiohttp/_http_parser.pyx", line 557, in aiohttp._http_parser.HttpParser.feed_data
aiohttp.http_exceptions.BadStatusLine: 400, message:
  Invalid method encountered:

    b'\x16\x03\x01\x06\xfe\x01'
      ^
2024-09-19 12:07:53.480 ERROR (MainThread) [aiohttp.server] Error handling request
Traceback (most recent call last):
  File "/usr/local/lib/python3.12/site-packages/aiohttp/web_protocol.py", line 350, in data_received
    messages, upgraded, tail = self._request_parser.feed_data(data)
                               ^^^^^^^^^^^^^^^^^^^^^^^^^^^^^^^^^^^^
  File "aiohttp/_http_parser.pyx", line 557, in aiohttp._http_parser.HttpParser.feed_data
aiohttp.http_exceptions.BadStatusLine: 400, message:
  Invalid method encountered:

    b'\x16\x03\x01\x06\xbe\x01'
      ^
2024-09-19 12:07:53.486 ERROR (MainThread) [aiohttp.server] Error handling request
Traceback (most recent call last):
  File "/usr/local/lib/python3.12/site-packages/aiohttp/web_protocol.py", line 350, in data_received
    messages, upgraded, tail = self._request_parser.feed_data(data)
                               ^^^^^^^^^^^^^^^^^^^^^^^^^^^^^^^^^^^^
  File "aiohttp/_http_parser.pyx", line 557, in aiohttp._http_parser.HttpParser.feed_data
aiohttp.http_exceptions.BadStatusLine: 400, message:
  Invalid method encountered:

    b'\x16\x03\x01\x07\x1e\x01'
      ^
2024-09-19 12:07:53.499 ERROR (MainThread) [aiohttp.server] Error handling request
Traceback (most recent call last):
  File "/usr/local/lib/python3.12/site-packages/aiohttp/web_protocol.py", line 350, in data_received
    messages, upgraded, tail = self._request_parser.feed_data(data)
                               ^^^^^^^^^^^^^^^^^^^^^^^^^^^^^^^^^^^^
  File "aiohttp/_http_parser.pyx", line 557, in aiohttp._http_parser.HttpParser.feed_data
aiohttp.http_exceptions.BadStatusLine: 400, message:
  Invalid method encountered:

    b'\x16\x03\x01\x07\x1e\x01'
      ^
2024-09-19 12:07:53.506 ERROR (MainThread) [aiohttp.server] Error handling request
Traceback (most recent call last):
  File "/usr/local/lib/python3.12/site-packages/aiohttp/web_protocol.py", line 350, in data_received
    messages, upgraded, tail = self._request_parser.feed_data(data)
                               ^^^^^^^^^^^^^^^^^^^^^^^^^^^^^^^^^^^^
  File "aiohttp/_http_parser.pyx", line 557, in aiohttp._http_parser.HttpParser.feed_data
aiohttp.http_exceptions.BadStatusLine: 400, message:
  Invalid method encountered:

    b'\x16\x03\x01\x06\xb2\x01'
      ^
2024-09-19 12:07:53.513 ERROR (MainThread) [aiohttp.server] Error handling request
Traceback (most recent call last):
  File "/usr/local/lib/python3.12/site-packages/aiohttp/web_protocol.py", line 350, in data_received
    messages, upgraded, tail = self._request_parser.feed_data(data)
                               ^^^^^^^^^^^^^^^^^^^^^^^^^^^^^^^^^^^^
  File "aiohttp/_http_parser.pyx", line 557, in aiohttp._http_parser.HttpParser.feed_data
aiohttp.http_exceptions.BadStatusLine: 400, message:
  Invalid method encountered:

    b'\x16\x03\x01\x06\xbe\x01'
      ^
2024-09-19 12:07:53.525 ERROR (MainThread) [aiohttp.server] Error handling request
Traceback (most recent call last):
  File "/usr/local/lib/python3.12/site-packages/aiohttp/web_protocol.py", line 350, in data_received
    messages, upgraded, tail = self._request_parser.feed_data(data)
                               ^^^^^^^^^^^^^^^^^^^^^^^^^^^^^^^^^^^^
  File "aiohttp/_http_parser.pyx", line 557, in aiohttp._http_parser.HttpParser.feed_data
aiohttp.http_exceptions.BadStatusLine: 400, message:
  Invalid method encountered:

    b'\x16\x03\x01\x06\xbe\x01'
      ^
2024-09-19 12:07:53.529 ERROR (MainThread) [aiohttp.server] Error handling request
Traceback (most recent call last):
  File "/usr/local/lib/python3.12/site-packages/aiohttp/web_protocol.py", line 350, in data_received
    messages, upgraded, tail = self._request_parser.feed_data(data)
                               ^^^^^^^^^^^^^^^^^^^^^^^^^^^^^^^^^^^^
  File "aiohttp/_http_parser.pyx", line 557, in aiohttp._http_parser.HttpParser.feed_data
aiohttp.http_exceptions.BadStatusLine: 400, message:
  Invalid method encountered:

    b'\x16\x03\x01\x06\xfe\x01'
      ^
2024-09-19 12:07:53.551 ERROR (MainThread) [aiohttp.server] Error handling request
Traceback (most recent call last):
  File "/usr/local/lib/python3.12/site-packages/aiohttp/web_protocol.py", line 350, in data_received
    messages, upgraded, tail = self._request_parser.feed_data(data)
                               ^^^^^^^^^^^^^^^^^^^^^^^^^^^^^^^^^^^^
  File "aiohttp/_http_parser.pyx", line 557, in aiohttp._http_parser.HttpParser.feed_data
aiohttp.http_exceptions.BadStatusLine: 400, message:
  Invalid method encountered:

    b'\x16\x03\x01\x07\x1e\x01'
      ^
2024-09-19 12:07:53.554 ERROR (MainThread) [aiohttp.server] Error handling request
Traceback (most recent call last):
  File "/usr/local/lib/python3.12/site-packages/aiohttp/web_protocol.py", line 350, in data_received
    messages, upgraded, tail = self._request_parser.feed_data(data)
                               ^^^^^^^^^^^^^^^^^^^^^^^^^^^^^^^^^^^^
  File "aiohttp/_http_parser.pyx", line 557, in aiohttp._http_parser.HttpParser.feed_data
aiohttp.http_exceptions.BadStatusLine: 400, message:
  Invalid method encountered:

    b'\x16\x03\x01\x06\xfe\x01'
      ^
2024-09-19 12:07:53.559 ERROR (MainThread) [aiohttp.server] Error handling request
Traceback (most recent call last):
  File "/usr/local/lib/python3.12/site-packages/aiohttp/web_protocol.py", line 350, in data_received
    messages, upgraded, tail = self._request_parser.feed_data(data)
                               ^^^^^^^^^^^^^^^^^^^^^^^^^^^^^^^^^^^^
  File "aiohttp/_http_parser.pyx", line 557, in aiohttp._http_parser.HttpParser.feed_data
aiohttp.http_exceptions.BadStatusLine: 400, message:
  Invalid method encountered:

    b'\x16\x03\x01\x06\xde\x01'
      ^
2024-09-19 12:07:53.570 ERROR (MainThread) [aiohttp.server] Error handling request
Traceback (most recent call last):
  File "/usr/local/lib/python3.12/site-packages/aiohttp/web_protocol.py", line 350, in data_received
    messages, upgraded, tail = self._request_parser.feed_data(data)
                               ^^^^^^^^^^^^^^^^^^^^^^^^^^^^^^^^^^^^
  File "aiohttp/_http_parser.pyx", line 557, in aiohttp._http_parser.HttpParser.feed_data
aiohttp.http_exceptions.BadStatusLine: 400, message:
  Invalid method encountered:

    b'\x16\x03\x01\x06\xde\x01'
      ^
2024-09-19 12:07:53.575 ERROR (MainThread) [aiohttp.server] Error handling request
Traceback (most recent call last):
  File "/usr/local/lib/python3.12/site-packages/aiohttp/web_protocol.py", line 350, in data_received
    messages, upgraded, tail = self._request_parser.feed_data(data)
                               ^^^^^^^^^^^^^^^^^^^^^^^^^^^^^^^^^^^^
  File "aiohttp/_http_parser.pyx", line 557, in aiohttp._http_parser.HttpParser.feed_data
aiohttp.http_exceptions.BadStatusLine: 400, message:
  Invalid method encountered:

    b'\x16\x03\x01\x06\xde\x01'
      ^
2024-09-19 12:07:53.589 ERROR (MainThread) [aiohttp.server] Error handling request
Traceback (most recent call last):
  File "/usr/local/lib/python3.12/site-packages/aiohttp/web_protocol.py", line 350, in data_received
    messages, upgraded, tail = self._request_parser.feed_data(data)
                               ^^^^^^^^^^^^^^^^^^^^^^^^^^^^^^^^^^^^
  File "aiohttp/_http_parser.pyx", line 557, in aiohttp._http_parser.HttpParser.feed_data
aiohttp.http_exceptions.BadStatusLine: 400, message:
  Invalid method encountered:

    b'\x16\x03\x01\x07\x1e\x01'
      ^
2024-09-19 12:07:53.601 ERROR (MainThread) [aiohttp.server] Error handling request
Traceback (most recent call last):
  File "/usr/local/lib/python3.12/site-packages/aiohttp/web_protocol.py", line 350, in data_received
    messages, upgraded, tail = self._request_parser.feed_data(data)
                               ^^^^^^^^^^^^^^^^^^^^^^^^^^^^^^^^^^^^
  File "aiohttp/_http_parser.pyx", line 557, in aiohttp._http_parser.HttpParser.feed_data
aiohttp.http_exceptions.BadStatusLine: 400, message:
  Invalid method encountered:

    b'\x16\x03\x01\x06\xbe\x01'
      ^
2024-09-19 12:07:53.609 ERROR (MainThread) [aiohttp.server] Error handling request
Traceback (most recent call last):
  File "/usr/local/lib/python3.12/site-packages/aiohttp/web_protocol.py", line 350, in data_received
    messages, upgraded, tail = self._request_parser.feed_data(data)
                               ^^^^^^^^^^^^^^^^^^^^^^^^^^^^^^^^^^^^
  File "aiohttp/_http_parser.pyx", line 557, in aiohttp._http_parser.HttpParser.feed_data
aiohttp.http_exceptions.BadStatusLine: 400, message:
  Invalid method encountered:

    b'\x16\x03\x01\x06\xde\x01'
      ^
2024-09-19 12:07:53.613 ERROR (MainThread) [aiohttp.server] Error handling request
Traceback (most recent call last):
  File "/usr/local/lib/python3.12/site-packages/aiohttp/web_protocol.py", line 350, in data_received
    messages, upgraded, tail = self._request_parser.feed_data(data)
                               ^^^^^^^^^^^^^^^^^^^^^^^^^^^^^^^^^^^^
  File "aiohttp/_http_parser.pyx", line 557, in aiohttp._http_parser.HttpParser.feed_data
aiohttp.http_exceptions.BadStatusLine: 400, message:
  Invalid method encountered:

    b'\x16\x03\x01\x06\xbe\x01'
      ^
2024-09-19 12:07:53.619 ERROR (MainThread) [aiohttp.server] Error handling request
Traceback (most recent call last):
  File "/usr/local/lib/python3.12/site-packages/aiohttp/web_protocol.py", line 350, in data_received
    messages, upgraded, tail = self._request_parser.feed_data(data)
                               ^^^^^^^^^^^^^^^^^^^^^^^^^^^^^^^^^^^^
  File "aiohttp/_http_parser.pyx", line 557, in aiohttp._http_parser.HttpParser.feed_data
aiohttp.http_exceptions.BadStatusLine: 400, message:
  Invalid method encountered:

    b'\x16\x03\x01\x06\xbe\x01'
      ^
2024-09-19 12:07:53.629 ERROR (MainThread) [aiohttp.server] Error handling request
Traceback (most recent call last):
  File "/usr/local/lib/python3.12/site-packages/aiohttp/web_protocol.py", line 350, in data_received
    messages, upgraded, tail = self._request_parser.feed_data(data)
                               ^^^^^^^^^^^^^^^^^^^^^^^^^^^^^^^^^^^^
  File "aiohttp/_http_parser.pyx", line 557, in aiohttp._http_parser.HttpParser.feed_data
aiohttp.http_exceptions.BadStatusLine: 400, message:
  Invalid method encountered:

    b'\x16\x03\x01\x06\xbe\x01'
      ^
2024-09-19 12:07:53.636 ERROR (MainThread) [aiohttp.server] Error handling request
Traceback (most recent call last):
  File "/usr/local/lib/python3.12/site-packages/aiohttp/web_protocol.py", line 350, in data_received
    messages, upgraded, tail = self._request_parser.feed_data(data)
                               ^^^^^^^^^^^^^^^^^^^^^^^^^^^^^^^^^^^^
  File "aiohttp/_http_parser.pyx", line 557, in aiohttp._http_parser.HttpParser.feed_data
aiohttp.http_exceptions.BadStatusLine: 400, message:
  Invalid method encountered:

    b'\x16\x03\x01\x06\xbe\x01'
      ^
2024-09-19 12:07:53.643 ERROR (MainThread) [aiohttp.server] Error handling request
Traceback (most recent call last):
  File "/usr/local/lib/python3.12/site-packages/aiohttp/web_protocol.py", line 350, in data_received
    messages, upgraded, tail = self._request_parser.feed_data(data)
                               ^^^^^^^^^^^^^^^^^^^^^^^^^^^^^^^^^^^^
  File "aiohttp/_http_parser.pyx", line 557, in aiohttp._http_parser.HttpParser.feed_data
aiohttp.http_exceptions.BadStatusLine: 400, message:
  Invalid method encountered:

    b'\x16\x03\x01\x06\xfe\x01'
      ^
2024-09-19 12:07:53.652 ERROR (MainThread) [aiohttp.server] Error handling request
Traceback (most recent call last):
  File "/usr/local/lib/python3.12/site-packages/aiohttp/web_protocol.py", line 350, in data_received
    messages, upgraded, tail = self._request_parser.feed_data(data)
                               ^^^^^^^^^^^^^^^^^^^^^^^^^^^^^^^^^^^^
  File "aiohttp/_http_parser.pyx", line 557, in aiohttp._http_parser.HttpParser.feed_data
aiohttp.http_exceptions.BadStatusLine: 400, message:
  Invalid method encountered:

    b'\x16\x03\x01\x07\x1e\x01'
      ^
2024-09-19 12:07:53.662 ERROR (MainThread) [aiohttp.server] Error handling request
Traceback (most recent call last):
  File "/usr/local/lib/python3.12/site-packages/aiohttp/web_protocol.py", line 350, in data_received
    messages, upgraded, tail = self._request_parser.feed_data(data)
                               ^^^^^^^^^^^^^^^^^^^^^^^^^^^^^^^^^^^^
  File "aiohttp/_http_parser.pyx", line 557, in aiohttp._http_parser.HttpParser.feed_data
aiohttp.http_exceptions.BadStatusLine: 400, message:
  Invalid method encountered:

    b'\x16\x03\x01\x06\xbe\x01'
      ^
2024-09-19 12:07:53.670 ERROR (MainThread) [aiohttp.server] Error handling request
Traceback (most recent call last):
  File "/usr/local/lib/python3.12/site-packages/aiohttp/web_protocol.py", line 350, in data_received
    messages, upgraded, tail = self._request_parser.feed_data(data)
                               ^^^^^^^^^^^^^^^^^^^^^^^^^^^^^^^^^^^^
  File "aiohttp/_http_parser.pyx", line 557, in aiohttp._http_parser.HttpParser.feed_data
aiohttp.http_exceptions.BadStatusLine: 400, message:
  Invalid method encountered:

    b'\x16\x03\x01\x07\x1e\x01'
      ^
2024-09-19 12:07:53.676 ERROR (MainThread) [aiohttp.server] Error handling request
Traceback (most recent call last):
  File "/usr/local/lib/python3.12/site-packages/aiohttp/web_protocol.py", line 350, in data_received
    messages, upgraded, tail = self._request_parser.feed_data(data)
                               ^^^^^^^^^^^^^^^^^^^^^^^^^^^^^^^^^^^^
  File "aiohttp/_http_parser.pyx", line 557, in aiohttp._http_parser.HttpParser.feed_data
aiohttp.http_exceptions.BadStatusLine: 400, message:
  Invalid method encountered:

    b'\x16\x03\x01\x06\xfe\x01'
      ^
2024-09-19 12:07:53.687 ERROR (MainThread) [aiohttp.server] Error handling request
Traceback (most recent call last):
  File "/usr/local/lib/python3.12/site-packages/aiohttp/web_protocol.py", line 350, in data_received
    messages, upgraded, tail = self._request_parser.feed_data(data)
                               ^^^^^^^^^^^^^^^^^^^^^^^^^^^^^^^^^^^^
  File "aiohttp/_http_parser.pyx", line 557, in aiohttp._http_parser.HttpParser.feed_data
aiohttp.http_exceptions.BadStatusLine: 400, message:
  Invalid method encountered:

    b'\x16\x03\x01\x06\xfe\x01'
      ^
2024-09-19 12:07:53.694 ERROR (MainThread) [aiohttp.server] Error handling request
Traceback (most recent call last):
  File "/usr/local/lib/python3.12/site-packages/aiohttp/web_protocol.py", line 350, in data_received
    messages, upgraded, tail = self._request_parser.feed_data(data)
                               ^^^^^^^^^^^^^^^^^^^^^^^^^^^^^^^^^^^^
  File "aiohttp/_http_parser.pyx", line 557, in aiohttp._http_parser.HttpParser.feed_data
aiohttp.http_exceptions.BadStatusLine: 400, message:
  Invalid method encountered:

    b'\x16\x03\x01\x06\xfe\x01'
      ^
2024-09-19 12:07:55.047 ERROR (MainThread) [aiohttp.server] Error handling request
Traceback (most recent call last):
  File "/usr/local/lib/python3.12/site-packages/aiohttp/web_protocol.py", line 350, in data_received
    messages, upgraded, tail = self._request_parser.feed_data(data)
                               ^^^^^^^^^^^^^^^^^^^^^^^^^^^^^^^^^^^^
  File "aiohttp/_http_parser.pyx", line 557, in aiohttp._http_parser.HttpParser.feed_data
aiohttp.http_exceptions.BadStatusLine: 400, message:
  Invalid method encountered:

    b'\x16\x03\x01\x06\xbe\x01'
      ^
2024-09-19 12:07:55.052 ERROR (MainThread) [aiohttp.server] Error handling request
Traceback (most recent call last):
  File "/usr/local/lib/python3.12/site-packages/aiohttp/web_protocol.py", line 350, in data_received
    messages, upgraded, tail = self._request_parser.feed_data(data)
                               ^^^^^^^^^^^^^^^^^^^^^^^^^^^^^^^^^^^^
  File "aiohttp/_http_parser.pyx", line 557, in aiohttp._http_parser.HttpParser.feed_data
aiohttp.http_exceptions.BadStatusLine: 400, message:
  Invalid method encountered:

    b'\x16\x03\x01\x06\xbe\x01'
      ^
2024-09-19 12:07:55.067 ERROR (MainThread) [aiohttp.server] Error handling request
Traceback (most recent call last):
  File "/usr/local/lib/python3.12/site-packages/aiohttp/web_protocol.py", line 350, in data_received
    messages, upgraded, tail = self._request_parser.feed_data(data)
                               ^^^^^^^^^^^^^^^^^^^^^^^^^^^^^^^^^^^^
  File "aiohttp/_http_parser.pyx", line 557, in aiohttp._http_parser.HttpParser.feed_data
aiohttp.http_exceptions.BadStatusLine: 400, message:
  Invalid method encountered:

    b'\x16\x03\x01\x06\xde\x01'
      ^
2024-09-19 12:07:55.077 ERROR (MainThread) [aiohttp.server] Error handling request
Traceback (most recent call last):
  File "/usr/local/lib/python3.12/site-packages/aiohttp/web_protocol.py", line 350, in data_received
    messages, upgraded, tail = self._request_parser.feed_data(data)
                               ^^^^^^^^^^^^^^^^^^^^^^^^^^^^^^^^^^^^
  File "aiohttp/_http_parser.pyx", line 557, in aiohttp._http_parser.HttpParser.feed_data
aiohttp.http_exceptions.BadStatusLine: 400, message:
  Invalid method encountered:

    b'\x16\x03\x01\x07\x1e\x01'
      ^
2024-09-19 12:07:55.161 ERROR (MainThread) [aiohttp.server] Error handling request
Traceback (most recent call last):
  File "/usr/local/lib/python3.12/site-packages/aiohttp/web_protocol.py", line 350, in data_received
    messages, upgraded, tail = self._request_parser.feed_data(data)
                               ^^^^^^^^^^^^^^^^^^^^^^^^^^^^^^^^^^^^
  File "aiohttp/_http_parser.pyx", line 557, in aiohttp._http_parser.HttpParser.feed_data
aiohttp.http_exceptions.BadStatusLine: 400, message:
  Invalid method encountered:

    b'\x16\x03\x01\x06\xbe\x01'
      ^
2024-09-19 12:07:55.167 ERROR (MainThread) [aiohttp.server] Error handling request
Traceback (most recent call last):
  File "/usr/local/lib/python3.12/site-packages/aiohttp/web_protocol.py", line 350, in data_received
    messages, upgraded, tail = self._request_parser.feed_data(data)
                               ^^^^^^^^^^^^^^^^^^^^^^^^^^^^^^^^^^^^
  File "aiohttp/_http_parser.pyx", line 557, in aiohttp._http_parser.HttpParser.feed_data
aiohttp.http_exceptions.BadStatusLine: 400, message:
  Invalid method encountered:

    b'\x16\x03\x01\x06\xbe\x01'
      ^
2024-09-19 12:07:55.172 ERROR (MainThread) [aiohttp.server] Error handling request
Traceback (most recent call last):
  File "/usr/local/lib/python3.12/site-packages/aiohttp/web_protocol.py", line 350, in data_received
    messages, upgraded, tail = self._request_parser.feed_data(data)
                               ^^^^^^^^^^^^^^^^^^^^^^^^^^^^^^^^^^^^
  File "aiohttp/_http_parser.pyx", line 557, in aiohttp._http_parser.HttpParser.feed_data
aiohttp.http_exceptions.BadStatusLine: 400, message:
  Invalid method encountered:

    b'\x16\x03\x01\x06\xbe\x01'
      ^
2024-09-19 12:07:55.177 ERROR (MainThread) [aiohttp.server] Error handling request
Traceback (most recent call last):
  File "/usr/local/lib/python3.12/site-packages/aiohttp/web_protocol.py", line 350, in data_received
    messages, upgraded, tail = self._request_parser.feed_data(data)
                               ^^^^^^^^^^^^^^^^^^^^^^^^^^^^^^^^^^^^
  File "aiohttp/_http_parser.pyx", line 557, in aiohttp._http_parser.HttpParser.feed_data
aiohttp.http_exceptions.BadStatusLine: 400, message:
  Invalid method encountered:

    b'\x16\x03\x01\x06\xbe\x01'
      ^
2024-09-19 12:07:55.183 ERROR (MainThread) [aiohttp.server] Error handling request
Traceback (most recent call last):
  File "/usr/local/lib/python3.12/site-packages/aiohttp/web_protocol.py", line 350, in data_received
    messages, upgraded, tail = self._request_parser.feed_data(data)
                               ^^^^^^^^^^^^^^^^^^^^^^^^^^^^^^^^^^^^
  File "aiohttp/_http_parser.pyx", line 557, in aiohttp._http_parser.HttpParser.feed_data
aiohttp.http_exceptions.BadStatusLine: 400, message:
  Invalid method encountered:

    b'\x16\x03\x01\x06\xde\x01'
      ^
2024-09-19 12:07:55.194 ERROR (MainThread) [aiohttp.server] Error handling request
Traceback (most recent call last):
  File "/usr/local/lib/python3.12/site-packages/aiohttp/web_protocol.py", line 350, in data_received
    messages, upgraded, tail = self._request_parser.feed_data(data)
                               ^^^^^^^^^^^^^^^^^^^^^^^^^^^^^^^^^^^^
  File "aiohttp/_http_parser.pyx", line 557, in aiohttp._http_parser.HttpParser.feed_data
aiohttp.http_exceptions.BadStatusLine: 400, message:
  Invalid method encountered:

    b'\x16\x03\x01\x06\xde\x01'
      ^
2024-09-19 12:07:55.206 ERROR (MainThread) [aiohttp.server] Error handling request
Traceback (most recent call last):
  File "/usr/local/lib/python3.12/site-packages/aiohttp/web_protocol.py", line 350, in data_received
    messages, upgraded, tail = self._request_parser.feed_data(data)
                               ^^^^^^^^^^^^^^^^^^^^^^^^^^^^^^^^^^^^
  File "aiohttp/_http_parser.pyx", line 557, in aiohttp._http_parser.HttpParser.feed_data
aiohttp.http_exceptions.BadStatusLine: 400, message:
  Invalid method encountered:

    b'\x16\x03\x01\x06\xfe\x01'
      ^
2024-09-19 12:07:55.211 ERROR (MainThread) [aiohttp.server] Error handling request
Traceback (most recent call last):
  File "/usr/local/lib/python3.12/site-packages/aiohttp/web_protocol.py", line 350, in data_received
    messages, upgraded, tail = self._request_parser.feed_data(data)
                               ^^^^^^^^^^^^^^^^^^^^^^^^^^^^^^^^^^^^
  File "aiohttp/_http_parser.pyx", line 557, in aiohttp._http_parser.HttpParser.feed_data
aiohttp.http_exceptions.BadStatusLine: 400, message:
  Invalid method encountered:

    b'\x16\x03\x01\x07\x1e\x01'
      ^
2024-09-19 12:07:55.216 ERROR (MainThread) [aiohttp.server] Error handling request
Traceback (most recent call last):
  File "/usr/local/lib/python3.12/site-packages/aiohttp/web_protocol.py", line 350, in data_received
    messages, upgraded, tail = self._request_parser.feed_data(data)
                               ^^^^^^^^^^^^^^^^^^^^^^^^^^^^^^^^^^^^
  File "aiohttp/_http_parser.pyx", line 557, in aiohttp._http_parser.HttpParser.feed_data
aiohttp.http_exceptions.BadStatusLine: 400, message:
  Invalid method encountered:

    b'\x16\x03\x01\x06\xfe\x01'
      ^
2024-09-19 12:07:55.225 ERROR (MainThread) [aiohttp.server] Error handling request
Traceback (most recent call last):
  File "/usr/local/lib/python3.12/site-packages/aiohttp/web_protocol.py", line 350, in data_received
    messages, upgraded, tail = self._request_parser.feed_data(data)
                               ^^^^^^^^^^^^^^^^^^^^^^^^^^^^^^^^^^^^
  File "aiohttp/_http_parser.pyx", line 557, in aiohttp._http_parser.HttpParser.feed_data
aiohttp.http_exceptions.BadStatusLine: 400, message:
  Invalid method encountered:

    b'\x16\x03\x01\x07\x1e\x01'
      ^
2024-09-19 12:07:55.227 ERROR (MainThread) [aiohttp.server] Error handling request
Traceback (most recent call last):
  File "/usr/local/lib/python3.12/site-packages/aiohttp/web_protocol.py", line 350, in data_received
    messages, upgraded, tail = self._request_parser.feed_data(data)
                               ^^^^^^^^^^^^^^^^^^^^^^^^^^^^^^^^^^^^
  File "aiohttp/_http_parser.pyx", line 557, in aiohttp._http_parser.HttpParser.feed_data
aiohttp.http_exceptions.BadStatusLine: 400, message:
  Invalid method encountered:

    b'\x16\x03\x01\x06\xb2\x01'
      ^
2024-09-19 12:07:55.232 ERROR (MainThread) [aiohttp.server] Error handling request
Traceback (most recent call last):
  File "/usr/local/lib/python3.12/site-packages/aiohttp/web_protocol.py", line 350, in data_received
    messages, upgraded, tail = self._request_parser.feed_data(data)
                               ^^^^^^^^^^^^^^^^^^^^^^^^^^^^^^^^^^^^
  File "aiohttp/_http_parser.pyx", line 557, in aiohttp._http_parser.HttpParser.feed_data
aiohttp.http_exceptions.BadStatusLine: 400, message:
  Invalid method encountered:

    b'\x16\x03\x01\x07\x1e\x01'
      ^
2024-09-19 12:07:55.249 ERROR (MainThread) [aiohttp.server] Error handling request
Traceback (most recent call last):
  File "/usr/local/lib/python3.12/site-packages/aiohttp/web_protocol.py", line 350, in data_received
    messages, upgraded, tail = self._request_parser.feed_data(data)
                               ^^^^^^^^^^^^^^^^^^^^^^^^^^^^^^^^^^^^
  File "aiohttp/_http_parser.pyx", line 557, in aiohttp._http_parser.HttpParser.feed_data
aiohttp.http_exceptions.BadStatusLine: 400, message:
  Invalid method encountered:

    b'\x16\x03\x01\x07\x1e\x01'
      ^
2024-09-19 12:07:55.253 ERROR (MainThread) [aiohttp.server] Error handling request
Traceback (most recent call last):
  File "/usr/local/lib/python3.12/site-packages/aiohttp/web_protocol.py", line 350, in data_received
    messages, upgraded, tail = self._request_parser.feed_data(data)
                               ^^^^^^^^^^^^^^^^^^^^^^^^^^^^^^^^^^^^
  File "aiohttp/_http_parser.pyx", line 557, in aiohttp._http_parser.HttpParser.feed_data
aiohttp.http_exceptions.BadStatusLine: 400, message:
  Invalid method encountered:

    b'\x16\x03\x01\x06\xbe\x01'
      ^
2024-09-19 12:07:55.262 ERROR (MainThread) [aiohttp.server] Error handling request
Traceback (most recent call last):
  File "/usr/local/lib/python3.12/site-packages/aiohttp/web_protocol.py", line 350, in data_received
    messages, upgraded, tail = self._request_parser.feed_data(data)
                               ^^^^^^^^^^^^^^^^^^^^^^^^^^^^^^^^^^^^
  File "aiohttp/_http_parser.pyx", line 557, in aiohttp._http_parser.HttpParser.feed_data
aiohttp.http_exceptions.BadStatusLine: 400, message:
  Invalid method encountered:

    b'\x16\x03\x01\x06\xde\x01'
      ^
2024-09-19 12:07:55.267 ERROR (MainThread) [aiohttp.server] Error handling request
Traceback (most recent call last):
  File "/usr/local/lib/python3.12/site-packages/aiohttp/web_protocol.py", line 350, in data_received
    messages, upgraded, tail = self._request_parser.feed_data(data)
                               ^^^^^^^^^^^^^^^^^^^^^^^^^^^^^^^^^^^^
  File "aiohttp/_http_parser.pyx", line 557, in aiohttp._http_parser.HttpParser.feed_data
aiohttp.http_exceptions.BadStatusLine: 400, message:
  Invalid method encountered:

    b'\x16\x03\x01\x06\xde\x01'
      ^
2024-09-19 12:07:55.272 ERROR (MainThread) [aiohttp.server] Error handling request
Traceback (most recent call last):
  File "/usr/local/lib/python3.12/site-packages/aiohttp/web_protocol.py", line 350, in data_received
    messages, upgraded, tail = self._request_parser.feed_data(data)
                               ^^^^^^^^^^^^^^^^^^^^^^^^^^^^^^^^^^^^
  File "aiohttp/_http_parser.pyx", line 557, in aiohttp._http_parser.HttpParser.feed_data
aiohttp.http_exceptions.BadStatusLine: 400, message:
  Invalid method encountered:

    b'\x16\x03\x01\x07\x1e\x01'
      ^
2024-09-19 12:07:55.283 ERROR (MainThread) [aiohttp.server] Error handling request
Traceback (most recent call last):
  File "/usr/local/lib/python3.12/site-packages/aiohttp/web_protocol.py", line 350, in data_received
    messages, upgraded, tail = self._request_parser.feed_data(data)
                               ^^^^^^^^^^^^^^^^^^^^^^^^^^^^^^^^^^^^
  File "aiohttp/_http_parser.pyx", line 557, in aiohttp._http_parser.HttpParser.feed_data
aiohttp.http_exceptions.BadStatusLine: 400, message:
  Invalid method encountered:

    b'\x16\x03\x01\x06\xde\x01'
      ^
2024-09-19 12:07:55.288 ERROR (MainThread) [aiohttp.server] Error handling request
Traceback (most recent call last):
  File "/usr/local/lib/python3.12/site-packages/aiohttp/web_protocol.py", line 350, in data_received
    messages, upgraded, tail = self._request_parser.feed_data(data)
                               ^^^^^^^^^^^^^^^^^^^^^^^^^^^^^^^^^^^^
  File "aiohttp/_http_parser.pyx", line 557, in aiohttp._http_parser.HttpParser.feed_data
aiohttp.http_exceptions.BadStatusLine: 400, message:
  Invalid method encountered:

    b'\x16\x03\x01\x06\xb2\x01'
      ^
2024-09-19 12:07:55.296 ERROR (MainThread) [aiohttp.server] Error handling request
Traceback (most recent call last):
  File "/usr/local/lib/python3.12/site-packages/aiohttp/web_protocol.py", line 350, in data_received
    messages, upgraded, tail = self._request_parser.feed_data(data)
                               ^^^^^^^^^^^^^^^^^^^^^^^^^^^^^^^^^^^^
  File "aiohttp/_http_parser.pyx", line 557, in aiohttp._http_parser.HttpParser.feed_data
aiohttp.http_exceptions.BadStatusLine: 400, message:
  Invalid method encountered:

    b'\x16\x03\x01\x07\x1e\x01'
      ^
2024-09-19 12:07:55.300 ERROR (MainThread) [aiohttp.server] Error handling request
Traceback (most recent call last):
  File "/usr/local/lib/python3.12/site-packages/aiohttp/web_protocol.py", line 350, in data_received
    messages, upgraded, tail = self._request_parser.feed_data(data)
                               ^^^^^^^^^^^^^^^^^^^^^^^^^^^^^^^^^^^^
  File "aiohttp/_http_parser.pyx", line 557, in aiohttp._http_parser.HttpParser.feed_data
aiohttp.http_exceptions.BadStatusLine: 400, message:
  Invalid method encountered:

    b'\x16\x03\x01\x06\xde\x01'
      ^
2024-09-19 12:07:55.313 ERROR (MainThread) [aiohttp.server] Error handling request
Traceback (most recent call last):
  File "/usr/local/lib/python3.12/site-packages/aiohttp/web_protocol.py", line 350, in data_received
    messages, upgraded, tail = self._request_parser.feed_data(data)
                               ^^^^^^^^^^^^^^^^^^^^^^^^^^^^^^^^^^^^
  File "aiohttp/_http_parser.pyx", line 557, in aiohttp._http_parser.HttpParser.feed_data
aiohttp.http_exceptions.BadStatusLine: 400, message:
  Invalid method encountered:

    b'\x16\x03\x01\x06\xde\x01'
      ^
2024-09-19 12:07:55.316 ERROR (MainThread) [aiohttp.server] Error handling request
Traceback (most recent call last):
  File "/usr/local/lib/python3.12/site-packages/aiohttp/web_protocol.py", line 350, in data_received
    messages, upgraded, tail = self._request_parser.feed_data(data)
                               ^^^^^^^^^^^^^^^^^^^^^^^^^^^^^^^^^^^^
  File "aiohttp/_http_parser.pyx", line 557, in aiohttp._http_parser.HttpParser.feed_data
aiohttp.http_exceptions.BadStatusLine: 400, message:
  Invalid method encountered:

    b'\x16\x03\x01\x06\xbe\x01'
      ^
2024-09-19 12:07:55.326 ERROR (MainThread) [aiohttp.server] Error handling request
Traceback (most recent call last):
  File "/usr/local/lib/python3.12/site-packages/aiohttp/web_protocol.py", line 350, in data_received
    messages, upgraded, tail = self._request_parser.feed_data(data)
                               ^^^^^^^^^^^^^^^^^^^^^^^^^^^^^^^^^^^^
  File "aiohttp/_http_parser.pyx", line 557, in aiohttp._http_parser.HttpParser.feed_data
aiohttp.http_exceptions.BadStatusLine: 400, message:
  Invalid method encountered:

    b'\x16\x03\x01\x06\xbe\x01'
      ^
2024-09-19 12:07:55.330 ERROR (MainThread) [aiohttp.server] Error handling request
Traceback (most recent call last):
  File "/usr/local/lib/python3.12/site-packages/aiohttp/web_protocol.py", line 350, in data_received
    messages, upgraded, tail = self._request_parser.feed_data(data)
                               ^^^^^^^^^^^^^^^^^^^^^^^^^^^^^^^^^^^^
  File "aiohttp/_http_parser.pyx", line 557, in aiohttp._http_parser.HttpParser.feed_data
aiohttp.http_exceptions.BadStatusLine: 400, message:
  Invalid method encountered:

    b'\x16\x03\x01\x06\xde\x01'
      ^
2024-09-19 12:07:55.341 ERROR (MainThread) [aiohttp.server] Error handling request
Traceback (most recent call last):
  File "/usr/local/lib/python3.12/site-packages/aiohttp/web_protocol.py", line 350, in data_received
    messages, upgraded, tail = self._request_parser.feed_data(data)
                               ^^^^^^^^^^^^^^^^^^^^^^^^^^^^^^^^^^^^
  File "aiohttp/_http_parser.pyx", line 557, in aiohttp._http_parser.HttpParser.feed_data
aiohttp.http_exceptions.BadStatusLine: 400, message:
  Invalid method encountered:

    b'\x16\x03\x01\x06\xbe\x01'
      ^
2024-09-19 12:07:55.353 ERROR (MainThread) [aiohttp.server] Error handling request
Traceback (most recent call last):
  File "/usr/local/lib/python3.12/site-packages/aiohttp/web_protocol.py", line 350, in data_received
    messages, upgraded, tail = self._request_parser.feed_data(data)
                               ^^^^^^^^^^^^^^^^^^^^^^^^^^^^^^^^^^^^
  File "aiohttp/_http_parser.pyx", line 557, in aiohttp._http_parser.HttpParser.feed_data
aiohttp.http_exceptions.BadStatusLine: 400, message:
  Invalid method encountered:

    b'\x16\x03\x01\x06\xfe\x01'
      ^
2024-09-19 12:07:55.363 ERROR (MainThread) [aiohttp.server] Error handling request
Traceback (most recent call last):
  File "/usr/local/lib/python3.12/site-packages/aiohttp/web_protocol.py", line 350, in data_received
    messages, upgraded, tail = self._request_parser.feed_data(data)
                               ^^^^^^^^^^^^^^^^^^^^^^^^^^^^^^^^^^^^
  File "aiohttp/_http_parser.pyx", line 557, in aiohttp._http_parser.HttpParser.feed_data
aiohttp.http_exceptions.BadStatusLine: 400, message:
  Invalid method encountered:

    b'\x16\x03\x01\x07\x1e\x01'
      ^
2024-09-19 12:07:55.369 ERROR (MainThread) [aiohttp.server] Error handling request
Traceback (most recent call last):
  File "/usr/local/lib/python3.12/site-packages/aiohttp/web_protocol.py", line 350, in data_received
    messages, upgraded, tail = self._request_parser.feed_data(data)
                               ^^^^^^^^^^^^^^^^^^^^^^^^^^^^^^^^^^^^
  File "aiohttp/_http_parser.pyx", line 557, in aiohttp._http_parser.HttpParser.feed_data
aiohttp.http_exceptions.BadStatusLine: 400, message:
  Invalid method encountered:

    b'\x16\x03\x01\x06\xfe\x01'
      ^
2024-09-19 12:07:55.380 ERROR (MainThread) [aiohttp.server] Error handling request
Traceback (most recent call last):
  File "/usr/local/lib/python3.12/site-packages/aiohttp/web_protocol.py", line 350, in data_received
    messages, upgraded, tail = self._request_parser.feed_data(data)
                               ^^^^^^^^^^^^^^^^^^^^^^^^^^^^^^^^^^^^
  File "aiohttp/_http_parser.pyx", line 557, in aiohttp._http_parser.HttpParser.feed_data
aiohttp.http_exceptions.BadStatusLine: 400, message:
  Invalid method encountered:

    b'\x16\x03\x01\x06\xfe\x01'
      ^
2024-09-19 12:07:55.384 ERROR (MainThread) [aiohttp.server] Error handling request
Traceback (most recent call last):
  File "/usr/local/lib/python3.12/site-packages/aiohttp/web_protocol.py", line 350, in data_received
    messages, upgraded, tail = self._request_parser.feed_data(data)
                               ^^^^^^^^^^^^^^^^^^^^^^^^^^^^^^^^^^^^
  File "aiohttp/_http_parser.pyx", line 557, in aiohttp._http_parser.HttpParser.feed_data
aiohttp.http_exceptions.BadStatusLine: 400, message:
  Invalid method encountered:

    b'\x16\x03\x01\x06\xde\x01'
      ^
2024-09-19 12:07:55.393 ERROR (MainThread) [aiohttp.server] Error handling request
Traceback (most recent call last):
  File "/usr/local/lib/python3.12/site-packages/aiohttp/web_protocol.py", line 350, in data_received
    messages, upgraded, tail = self._request_parser.feed_data(data)
                               ^^^^^^^^^^^^^^^^^^^^^^^^^^^^^^^^^^^^
  File "aiohttp/_http_parser.pyx", line 557, in aiohttp._http_parser.HttpParser.feed_data
aiohttp.http_exceptions.BadStatusLine: 400, message:
  Invalid method encountered:

    b'\x16\x03\x01\x06\xbe\x01'
      ^
2024-09-19 12:07:55.402 ERROR (MainThread) [aiohttp.server] Error handling request
Traceback (most recent call last):
  File "/usr/local/lib/python3.12/site-packages/aiohttp/web_protocol.py", line 350, in data_received
    messages, upgraded, tail = self._request_parser.feed_data(data)
                               ^^^^^^^^^^^^^^^^^^^^^^^^^^^^^^^^^^^^
  File "aiohttp/_http_parser.pyx", line 557, in aiohttp._http_parser.HttpParser.feed_data
aiohttp.http_exceptions.BadStatusLine: 400, message:
  Invalid method encountered:

    b'\x16\x03\x01\x06\xbe\x01'
      ^
2024-09-19 12:07:55.412 ERROR (MainThread) [aiohttp.server] Error handling request
Traceback (most recent call last):
  File "/usr/local/lib/python3.12/site-packages/aiohttp/web_protocol.py", line 350, in data_received
    messages, upgraded, tail = self._request_parser.feed_data(data)
                               ^^^^^^^^^^^^^^^^^^^^^^^^^^^^^^^^^^^^
  File "aiohttp/_http_parser.pyx", line 557, in aiohttp._http_parser.HttpParser.feed_data
aiohttp.http_exceptions.BadStatusLine: 400, message:
  Invalid method encountered:

    b'\x16\x03\x01\x06\xfe\x01'
      ^
2024-09-19 12:07:55.416 ERROR (MainThread) [aiohttp.server] Error handling request
Traceback (most recent call last):
  File "/usr/local/lib/python3.12/site-packages/aiohttp/web_protocol.py", line 350, in data_received
    messages, upgraded, tail = self._request_parser.feed_data(data)
                               ^^^^^^^^^^^^^^^^^^^^^^^^^^^^^^^^^^^^
  File "aiohttp/_http_parser.pyx", line 557, in aiohttp._http_parser.HttpParser.feed_data
aiohttp.http_exceptions.BadStatusLine: 400, message:
  Invalid method encountered:

    b'\x16\x03\x01\x07\x1e\x01'
      ^
2024-09-19 12:07:55.424 ERROR (MainThread) [aiohttp.server] Error handling request
Traceback (most recent call last):
  File "/usr/local/lib/python3.12/site-packages/aiohttp/web_protocol.py", line 350, in data_received
    messages, upgraded, tail = self._request_parser.feed_data(data)
                               ^^^^^^^^^^^^^^^^^^^^^^^^^^^^^^^^^^^^
  File "aiohttp/_http_parser.pyx", line 557, in aiohttp._http_parser.HttpParser.feed_data
aiohttp.http_exceptions.BadStatusLine: 400, message:
  Invalid method encountered:

    b'\x16\x03\x01\x06\xfe\x01'
      ^
2024-09-19 12:07:55.432 ERROR (MainThread) [aiohttp.server] Error handling request
Traceback (most recent call last):
  File "/usr/local/lib/python3.12/site-packages/aiohttp/web_protocol.py", line 350, in data_received
    messages, upgraded, tail = self._request_parser.feed_data(data)
                               ^^^^^^^^^^^^^^^^^^^^^^^^^^^^^^^^^^^^
  File "aiohttp/_http_parser.pyx", line 557, in aiohttp._http_parser.HttpParser.feed_data
aiohttp.http_exceptions.BadStatusLine: 400, message:
  Invalid method encountered:

    b'\x16\x03\x01\x06\xde\x01'
      ^
2024-09-19 12:07:55.439 ERROR (MainThread) [aiohttp.server] Error handling request
Traceback (most recent call last):
  File "/usr/local/lib/python3.12/site-packages/aiohttp/web_protocol.py", line 350, in data_received
    messages, upgraded, tail = self._request_parser.feed_data(data)
                               ^^^^^^^^^^^^^^^^^^^^^^^^^^^^^^^^^^^^
  File "aiohttp/_http_parser.pyx", line 557, in aiohttp._http_parser.HttpParser.feed_data
aiohttp.http_exceptions.BadStatusLine: 400, message:
  Invalid method encountered:

    b'\x16\x03\x01\x06\xbe\x01'
      ^
2024-09-19 12:07:55.446 ERROR (MainThread) [aiohttp.server] Error handling request
Traceback (most recent call last):
  File "/usr/local/lib/python3.12/site-packages/aiohttp/web_protocol.py", line 350, in data_received
    messages, upgraded, tail = self._request_parser.feed_data(data)
                               ^^^^^^^^^^^^^^^^^^^^^^^^^^^^^^^^^^^^
  File "aiohttp/_http_parser.pyx", line 557, in aiohttp._http_parser.HttpParser.feed_data
aiohttp.http_exceptions.BadStatusLine: 400, message:
  Invalid method encountered:

    b'\x16\x03\x01\x06\xfe\x01'
      ^
2024-09-19 12:07:55.466 ERROR (MainThread) [aiohttp.server] Error handling request
Traceback (most recent call last):
  File "/usr/local/lib/python3.12/site-packages/aiohttp/web_protocol.py", line 350, in data_received
    messages, upgraded, tail = self._request_parser.feed_data(data)
                               ^^^^^^^^^^^^^^^^^^^^^^^^^^^^^^^^^^^^
  File "aiohttp/_http_parser.pyx", line 557, in aiohttp._http_parser.HttpParser.feed_data
aiohttp.http_exceptions.BadStatusLine: 400, message:
  Invalid method encountered:

    b'\x16\x03\x01\x06\xde\x01'
      ^
2024-09-19 12:07:57.001 ERROR (MainThread) [aiohttp.server] Error handling request
Traceback (most recent call last):
  File "/usr/local/lib/python3.12/site-packages/aiohttp/web_protocol.py", line 350, in data_received
    messages, upgraded, tail = self._request_parser.feed_data(data)
                               ^^^^^^^^^^^^^^^^^^^^^^^^^^^^^^^^^^^^
  File "aiohttp/_http_parser.pyx", line 557, in aiohttp._http_parser.HttpParser.feed_data
aiohttp.http_exceptions.BadStatusLine: 400, message:
  Invalid method encountered:

    b'\x16\x03\x01\x06\xbe\x01'
      ^
2024-09-19 12:07:57.019 ERROR (MainThread) [aiohttp.server] Error handling request
Traceback (most recent call last):
  File "/usr/local/lib/python3.12/site-packages/aiohttp/web_protocol.py", line 350, in data_received
    messages, upgraded, tail = self._request_parser.feed_data(data)
                               ^^^^^^^^^^^^^^^^^^^^^^^^^^^^^^^^^^^^
  File "aiohttp/_http_parser.pyx", line 557, in aiohttp._http_parser.HttpParser.feed_data
aiohttp.http_exceptions.BadStatusLine: 400, message:
  Invalid method encountered:

    b'\x16\x03\x01\x06\xbe\x01'
      ^
2024-09-19 12:08:03.574 ERROR (MainThread) [aiohttp.server] Error handling request
Traceback (most recent call last):
  File "/usr/local/lib/python3.12/site-packages/aiohttp/web_protocol.py", line 350, in data_received
    messages, upgraded, tail = self._request_parser.feed_data(data)
                               ^^^^^^^^^^^^^^^^^^^^^^^^^^^^^^^^^^^^
  File "aiohttp/_http_parser.pyx", line 557, in aiohttp._http_parser.HttpParser.feed_data
aiohttp.http_exceptions.BadStatusLine: 400, message:
  Invalid method encountered:

    b'\x16\x03\x01\x06\xbe\x01'
      ^
2024-09-19 12:08:03.595 ERROR (MainThread) [aiohttp.server] Error handling request
Traceback (most recent call last):
  File "/usr/local/lib/python3.12/site-packages/aiohttp/web_protocol.py", line 350, in data_received
    messages, upgraded, tail = self._request_parser.feed_data(data)
                               ^^^^^^^^^^^^^^^^^^^^^^^^^^^^^^^^^^^^
  File "aiohttp/_http_parser.pyx", line 557, in aiohttp._http_parser.HttpParser.feed_data
aiohttp.http_exceptions.BadStatusLine: 400, message:
  Invalid method encountered:

    b'\x16\x03\x01\x06\xfe\x01'
      ^
2024-09-19 12:08:03.905 ERROR (MainThread) [aiohttp.server] Error handling request
Traceback (most recent call last):
  File "/usr/local/lib/python3.12/site-packages/aiohttp/web_protocol.py", line 350, in data_received
    messages, upgraded, tail = self._request_parser.feed_data(data)
                               ^^^^^^^^^^^^^^^^^^^^^^^^^^^^^^^^^^^^
  File "aiohttp/_http_parser.pyx", line 557, in aiohttp._http_parser.HttpParser.feed_data
aiohttp.http_exceptions.BadStatusLine: 400, message:
  Invalid method encountered:

    b'\x16\x03\x01\x06\xfe\x01'
      ^
2024-09-19 12:08:03.910 ERROR (MainThread) [aiohttp.server] Error handling request
Traceback (most recent call last):
  File "/usr/local/lib/python3.12/site-packages/aiohttp/web_protocol.py", line 350, in data_received
    messages, upgraded, tail = self._request_parser.feed_data(data)
                               ^^^^^^^^^^^^^^^^^^^^^^^^^^^^^^^^^^^^
  File "aiohttp/_http_parser.pyx", line 557, in aiohttp._http_parser.HttpParser.feed_data
aiohttp.http_exceptions.BadStatusLine: 400, message:
  Invalid method encountered:

    b'\x16\x03\x01\x06\xde\x01'
      ^
2024-09-19 12:08:03.930 ERROR (MainThread) [aiohttp.server] Error handling request
Traceback (most recent call last):
  File "/usr/local/lib/python3.12/site-packages/aiohttp/web_protocol.py", line 350, in data_received
    messages, upgraded, tail = self._request_parser.feed_data(data)
                               ^^^^^^^^^^^^^^^^^^^^^^^^^^^^^^^^^^^^
  File "aiohttp/_http_parser.pyx", line 557, in aiohttp._http_parser.HttpParser.feed_data
aiohttp.http_exceptions.BadStatusLine: 400, message:
  Invalid method encountered:

    b'\x16\x03\x01\x07\x1e\x01'
      ^
2024-09-19 12:08:03.938 ERROR (MainThread) [aiohttp.server] Error handling request
Traceback (most recent call last):
  File "/usr/local/lib/python3.12/site-packages/aiohttp/web_protocol.py", line 350, in data_received
    messages, upgraded, tail = self._request_parser.feed_data(data)
                               ^^^^^^^^^^^^^^^^^^^^^^^^^^^^^^^^^^^^
  File "aiohttp/_http_parser.pyx", line 557, in aiohttp._http_parser.HttpParser.feed_data
aiohttp.http_exceptions.BadStatusLine: 400, message:
  Invalid method encountered:

    b'\x16\x03\x01\x07\x1e\x01'
      ^
2024-09-19 12:08:06.471 ERROR (MainThread) [aiohttp.server] Error handling request
Traceback (most recent call last):
  File "/usr/local/lib/python3.12/site-packages/aiohttp/web_protocol.py", line 350, in data_received
    messages, upgraded, tail = self._request_parser.feed_data(data)
                               ^^^^^^^^^^^^^^^^^^^^^^^^^^^^^^^^^^^^
  File "aiohttp/_http_parser.pyx", line 557, in aiohttp._http_parser.HttpParser.feed_data
aiohttp.http_exceptions.BadStatusLine: 400, message:
  Invalid method encountered:

    b'\x16\x03\x01'
      ^
2024-09-19 12:08:10.950 ERROR (MainThread) [aiohttp.server] Error handling request
Traceback (most recent call last):
  File "/usr/local/lib/python3.12/site-packages/aiohttp/web_protocol.py", line 350, in data_received
    messages, upgraded, tail = self._request_parser.feed_data(data)
                               ^^^^^^^^^^^^^^^^^^^^^^^^^^^^^^^^^^^^
  File "aiohttp/_http_parser.pyx", line 557, in aiohttp._http_parser.HttpParser.feed_data
aiohttp.http_exceptions.BadStatusLine: 400, message:
  Invalid method encountered:

    b'\x16\x03\x01\x06\xde\x01'
      ^
2024-09-19 12:08:10.955 ERROR (MainThread) [aiohttp.server] Error handling request
Traceback (most recent call last):
  File "/usr/local/lib/python3.12/site-packages/aiohttp/web_protocol.py", line 350, in data_received
    messages, upgraded, tail = self._request_parser.feed_data(data)
                               ^^^^^^^^^^^^^^^^^^^^^^^^^^^^^^^^^^^^
  File "aiohttp/_http_parser.pyx", line 557, in aiohttp._http_parser.HttpParser.feed_data
aiohttp.http_exceptions.BadStatusLine: 400, message:
  Invalid method encountered:

    b'\x16\x03\x01\x07\x1e\x01'
      ^
2024-09-19 12:08:10.964 ERROR (MainThread) [aiohttp.server] Error handling request
Traceback (most recent call last):
  File "/usr/local/lib/python3.12/site-packages/aiohttp/web_protocol.py", line 350, in data_received
    messages, upgraded, tail = self._request_parser.feed_data(data)
                               ^^^^^^^^^^^^^^^^^^^^^^^^^^^^^^^^^^^^
  File "aiohttp/_http_parser.pyx", line 557, in aiohttp._http_parser.HttpParser.feed_data
aiohttp.http_exceptions.BadStatusLine: 400, message:
  Invalid method encountered:

    b'\x16\x03\x01\x06\xbe\x01'
      ^
2024-09-19 12:08:11.064 ERROR (MainThread) [aiohttp.server] Error handling request
Traceback (most recent call last):
  File "/usr/local/lib/python3.12/site-packages/aiohttp/web_protocol.py", line 350, in data_received
    messages, upgraded, tail = self._request_parser.feed_data(data)
                               ^^^^^^^^^^^^^^^^^^^^^^^^^^^^^^^^^^^^
  File "aiohttp/_http_parser.pyx", line 557, in aiohttp._http_parser.HttpParser.feed_data
aiohttp.http_exceptions.BadStatusLine: 400, message:
  Invalid method encountered:

    b'\x16\x03\x01\x06\xfe\x01'
      ^
2024-09-19 12:08:11.076 ERROR (MainThread) [aiohttp.server] Error handling request
Traceback (most recent call last):
  File "/usr/local/lib/python3.12/site-packages/aiohttp/web_protocol.py", line 350, in data_received
    messages, upgraded, tail = self._request_parser.feed_data(data)
                               ^^^^^^^^^^^^^^^^^^^^^^^^^^^^^^^^^^^^
  File "aiohttp/_http_parser.pyx", line 557, in aiohttp._http_parser.HttpParser.feed_data
aiohttp.http_exceptions.BadStatusLine: 400, message:
  Invalid method encountered:

    b'\x16\x03\x01\x06\xfe\x01'
      ^
2024-09-19 12:08:11.080 ERROR (MainThread) [aiohttp.server] Error handling request
Traceback (most recent call last):
  File "/usr/local/lib/python3.12/site-packages/aiohttp/web_protocol.py", line 350, in data_received
    messages, upgraded, tail = self._request_parser.feed_data(data)
                               ^^^^^^^^^^^^^^^^^^^^^^^^^^^^^^^^^^^^
  File "aiohttp/_http_parser.pyx", line 557, in aiohttp._http_parser.HttpParser.feed_data
aiohttp.http_exceptions.BadStatusLine: 400, message:
  Invalid method encountered:

    b'\x16\x03\x01\x07\x1e\x01'
      ^
2024-09-19 12:08:12.438 ERROR (MainThread) [aiohttp.server] Error handling request
Traceback (most recent call last):
  File "/usr/local/lib/python3.12/site-packages/aiohttp/web_protocol.py", line 350, in data_received
    messages, upgraded, tail = self._request_parser.feed_data(data)
                               ^^^^^^^^^^^^^^^^^^^^^^^^^^^^^^^^^^^^
  File "aiohttp/_http_parser.pyx", line 557, in aiohttp._http_parser.HttpParser.feed_data
aiohttp.http_exceptions.BadStatusLine: 400, message:
  Invalid method encountered:

    b'\x16\x03\x01\x07\x1e\x01'
      ^
2024-09-19 12:08:12.444 ERROR (MainThread) [aiohttp.server] Error handling request
Traceback (most recent call last):
  File "/usr/local/lib/python3.12/site-packages/aiohttp/web_protocol.py", line 350, in data_received
    messages, upgraded, tail = self._request_parser.feed_data(data)
                               ^^^^^^^^^^^^^^^^^^^^^^^^^^^^^^^^^^^^
  File "aiohttp/_http_parser.pyx", line 557, in aiohttp._http_parser.HttpParser.feed_data
aiohttp.http_exceptions.BadStatusLine: 400, message:
  Invalid method encountered:

    b'\x16\x03\x01\x06\xbe\x01'
      ^
2024-09-19 12:08:12.453 ERROR (MainThread) [aiohttp.server] Error handling request
Traceback (most recent call last):
  File "/usr/local/lib/python3.12/site-packages/aiohttp/web_protocol.py", line 350, in data_received
    messages, upgraded, tail = self._request_parser.feed_data(data)
                               ^^^^^^^^^^^^^^^^^^^^^^^^^^^^^^^^^^^^
  File "aiohttp/_http_parser.pyx", line 557, in aiohttp._http_parser.HttpParser.feed_data
aiohttp.http_exceptions.BadStatusLine: 400, message:
  Invalid method encountered:

    b'\x16\x03\x01\x06\xbe\x01'
      ^
2024-09-19 12:08:12.461 ERROR (MainThread) [aiohttp.server] Error handling request
Traceback (most recent call last):
  File "/usr/local/lib/python3.12/site-packages/aiohttp/web_protocol.py", line 350, in data_received
    messages, upgraded, tail = self._request_parser.feed_data(data)
                               ^^^^^^^^^^^^^^^^^^^^^^^^^^^^^^^^^^^^
  File "aiohttp/_http_parser.pyx", line 557, in aiohttp._http_parser.HttpParser.feed_data
aiohttp.http_exceptions.BadStatusLine: 400, message:
  Invalid method encountered:

    b'\x16\x03\x01\x06\xbe\x01'
      ^
2024-09-19 12:08:12.471 ERROR (MainThread) [aiohttp.server] Error handling request
Traceback (most recent call last):
  File "/usr/local/lib/python3.12/site-packages/aiohttp/web_protocol.py", line 350, in data_received
    messages, upgraded, tail = self._request_parser.feed_data(data)
                               ^^^^^^^^^^^^^^^^^^^^^^^^^^^^^^^^^^^^
  File "aiohttp/_http_parser.pyx", line 557, in aiohttp._http_parser.HttpParser.feed_data
aiohttp.http_exceptions.BadStatusLine: 400, message:
  Invalid method encountered:

    b'\x16\x03\x01\x06\xfe\x01'
      ^
2024-09-19 12:08:12.477 ERROR (MainThread) [aiohttp.server] Error handling request
Traceback (most recent call last):
  File "/usr/local/lib/python3.12/site-packages/aiohttp/web_protocol.py", line 350, in data_received
    messages, upgraded, tail = self._request_parser.feed_data(data)
                               ^^^^^^^^^^^^^^^^^^^^^^^^^^^^^^^^^^^^
  File "aiohttp/_http_parser.pyx", line 557, in aiohttp._http_parser.HttpParser.feed_data
aiohttp.http_exceptions.BadStatusLine: 400, message:
  Invalid method encountered:

    b'\x16\x03\x01\x06\xde\x01'
      ^
2024-09-19 12:08:13.156 ERROR (MainThread) [aiohttp.server] Error handling request
Traceback (most recent call last):
  File "/usr/local/lib/python3.12/site-packages/aiohttp/web_protocol.py", line 350, in data_received
    messages, upgraded, tail = self._request_parser.feed_data(data)
                               ^^^^^^^^^^^^^^^^^^^^^^^^^^^^^^^^^^^^
  File "aiohttp/_http_parser.pyx", line 557, in aiohttp._http_parser.HttpParser.feed_data
aiohttp.http_exceptions.BadStatusLine: 400, message:
  Invalid method encountered:

    b'\x16\x03\x01\x06\xde\x01'
      ^
2024-09-19 12:08:13.168 ERROR (MainThread) [aiohttp.server] Error handling request
Traceback (most recent call last):
  File "/usr/local/lib/python3.12/site-packages/aiohttp/web_protocol.py", line 350, in data_received
    messages, upgraded, tail = self._request_parser.feed_data(data)
                               ^^^^^^^^^^^^^^^^^^^^^^^^^^^^^^^^^^^^
  File "aiohttp/_http_parser.pyx", line 557, in aiohttp._http_parser.HttpParser.feed_data
aiohttp.http_exceptions.BadStatusLine: 400, message:
  Invalid method encountered:

    b'\x16\x03\x01\x06\xbe\x01'
      ^
2024-09-19 12:08:13.172 ERROR (MainThread) [aiohttp.server] Error handling request
Traceback (most recent call last):
  File "/usr/local/lib/python3.12/site-packages/aiohttp/web_protocol.py", line 350, in data_received
    messages, upgraded, tail = self._request_parser.feed_data(data)
                               ^^^^^^^^^^^^^^^^^^^^^^^^^^^^^^^^^^^^
  File "aiohttp/_http_parser.pyx", line 557, in aiohttp._http_parser.HttpParser.feed_data
aiohttp.http_exceptions.BadStatusLine: 400, message:
  Invalid method encountered:

    b'\x16\x03\x01\x06\xbe\x01'
      ^
2024-09-19 12:08:13.182 ERROR (MainThread) [aiohttp.server] Error handling request
Traceback (most recent call last):
  File "/usr/local/lib/python3.12/site-packages/aiohttp/web_protocol.py", line 350, in data_received
    messages, upgraded, tail = self._request_parser.feed_data(data)
                               ^^^^^^^^^^^^^^^^^^^^^^^^^^^^^^^^^^^^
  File "aiohttp/_http_parser.pyx", line 557, in aiohttp._http_parser.HttpParser.feed_data
aiohttp.http_exceptions.BadStatusLine: 400, message:
  Invalid method encountered:

    b'\x16\x03\x01\x06\xbe\x01'
      ^
2024-09-19 12:08:13.204 ERROR (MainThread) [aiohttp.server] Error handling request
Traceback (most recent call last):
  File "/usr/local/lib/python3.12/site-packages/aiohttp/web_protocol.py", line 350, in data_received
    messages, upgraded, tail = self._request_parser.feed_data(data)
                               ^^^^^^^^^^^^^^^^^^^^^^^^^^^^^^^^^^^^
  File "aiohttp/_http_parser.pyx", line 557, in aiohttp._http_parser.HttpParser.feed_data
aiohttp.http_exceptions.BadStatusLine: 400, message:
  Invalid method encountered:

    b'\x16\x03\x01\x06\xfe\x01'
      ^
2024-09-19 12:08:13.214 ERROR (MainThread) [aiohttp.server] Error handling request
Traceback (most recent call last):
  File "/usr/local/lib/python3.12/site-packages/aiohttp/web_protocol.py", line 350, in data_received
    messages, upgraded, tail = self._request_parser.feed_data(data)
                               ^^^^^^^^^^^^^^^^^^^^^^^^^^^^^^^^^^^^
  File "aiohttp/_http_parser.pyx", line 557, in aiohttp._http_parser.HttpParser.feed_data
aiohttp.http_exceptions.BadStatusLine: 400, message:
  Invalid method encountered:

    b'\x16\x03\x01\x06\xfe\x01'
      ^
2024-09-19 12:08:13.745 ERROR (MainThread) [aiohttp.server] Error handling request
Traceback (most recent call last):
  File "/usr/local/lib/python3.12/site-packages/aiohttp/web_protocol.py", line 350, in data_received
    messages, upgraded, tail = self._request_parser.feed_data(data)
                               ^^^^^^^^^^^^^^^^^^^^^^^^^^^^^^^^^^^^
  File "aiohttp/_http_parser.pyx", line 557, in aiohttp._http_parser.HttpParser.feed_data
aiohttp.http_exceptions.BadStatusLine: 400, message:
  Invalid method encountered:

    b'\x16\x03\x01\x07\x1e\x01'
      ^
2024-09-19 12:08:13.753 ERROR (MainThread) [aiohttp.server] Error handling request
Traceback (most recent call last):
  File "/usr/local/lib/python3.12/site-packages/aiohttp/web_protocol.py", line 350, in data_received
    messages, upgraded, tail = self._request_parser.feed_data(data)
                               ^^^^^^^^^^^^^^^^^^^^^^^^^^^^^^^^^^^^
  File "aiohttp/_http_parser.pyx", line 557, in aiohttp._http_parser.HttpParser.feed_data
aiohttp.http_exceptions.BadStatusLine: 400, message:
  Invalid method encountered:

    b'\x16\x03\x01\x06\xde\x01'
      ^
2024-09-19 12:08:13.760 ERROR (MainThread) [aiohttp.server] Error handling request
Traceback (most recent call last):
  File "/usr/local/lib/python3.12/site-packages/aiohttp/web_protocol.py", line 350, in data_received
    messages, upgraded, tail = self._request_parser.feed_data(data)
                               ^^^^^^^^^^^^^^^^^^^^^^^^^^^^^^^^^^^^
  File "aiohttp/_http_parser.pyx", line 557, in aiohttp._http_parser.HttpParser.feed_data
aiohttp.http_exceptions.BadStatusLine: 400, message:
  Invalid method encountered:

    b'\x16\x03\x01\x07\x1e\x01'
      ^
2024-09-19 12:08:13.770 ERROR (MainThread) [aiohttp.server] Error handling request
Traceback (most recent call last):
  File "/usr/local/lib/python3.12/site-packages/aiohttp/web_protocol.py", line 350, in data_received
    messages, upgraded, tail = self._request_parser.feed_data(data)
                               ^^^^^^^^^^^^^^^^^^^^^^^^^^^^^^^^^^^^
  File "aiohttp/_http_parser.pyx", line 557, in aiohttp._http_parser.HttpParser.feed_data
aiohttp.http_exceptions.BadStatusLine: 400, message:
  Invalid method encountered:

    b'\x16\x03\x01\x07\x1e\x01'
      ^
2024-09-19 12:08:13.778 ERROR (MainThread) [aiohttp.server] Error handling request
Traceback (most recent call last):
  File "/usr/local/lib/python3.12/site-packages/aiohttp/web_protocol.py", line 350, in data_received
    messages, upgraded, tail = self._request_parser.feed_data(data)
                               ^^^^^^^^^^^^^^^^^^^^^^^^^^^^^^^^^^^^
  File "aiohttp/_http_parser.pyx", line 557, in aiohttp._http_parser.HttpParser.feed_data
aiohttp.http_exceptions.BadStatusLine: 400, message:
  Invalid method encountered:

    b'\x16\x03\x01\x07\x1e\x01'
      ^
2024-09-19 12:08:13.785 ERROR (MainThread) [aiohttp.server] Error handling request
Traceback (most recent call last):
  File "/usr/local/lib/python3.12/site-packages/aiohttp/web_protocol.py", line 350, in data_received
    messages, upgraded, tail = self._request_parser.feed_data(data)
                               ^^^^^^^^^^^^^^^^^^^^^^^^^^^^^^^^^^^^
  File "aiohttp/_http_parser.pyx", line 557, in aiohttp._http_parser.HttpParser.feed_data
aiohttp.http_exceptions.BadStatusLine: 400, message:
  Invalid method encountered:

    b'\x16\x03\x01\x06\xfe\x01'
      ^
2024-09-19 12:08:14.292 ERROR (MainThread) [aiohttp.server] Error handling request
Traceback (most recent call last):
  File "/usr/local/lib/python3.12/site-packages/aiohttp/web_protocol.py", line 350, in data_received
    messages, upgraded, tail = self._request_parser.feed_data(data)
                               ^^^^^^^^^^^^^^^^^^^^^^^^^^^^^^^^^^^^
  File "aiohttp/_http_parser.pyx", line 557, in aiohttp._http_parser.HttpParser.feed_data
aiohttp.http_exceptions.BadStatusLine: 400, message:
  Invalid method encountered:

    b'\x16\x03\x01\x06\xbe\x01'
      ^
2024-09-19 12:08:14.298 ERROR (MainThread) [aiohttp.server] Error handling request
Traceback (most recent call last):
  File "/usr/local/lib/python3.12/site-packages/aiohttp/web_protocol.py", line 350, in data_received
    messages, upgraded, tail = self._request_parser.feed_data(data)
                               ^^^^^^^^^^^^^^^^^^^^^^^^^^^^^^^^^^^^
  File "aiohttp/_http_parser.pyx", line 557, in aiohttp._http_parser.HttpParser.feed_data
aiohttp.http_exceptions.BadStatusLine: 400, message:
  Invalid method encountered:

    b'\x16\x03\x01\x06\xfe\x01'
      ^
2024-09-19 12:08:14.303 ERROR (MainThread) [aiohttp.server] Error handling request
Traceback (most recent call last):
  File "/usr/local/lib/python3.12/site-packages/aiohttp/web_protocol.py", line 350, in data_received
    messages, upgraded, tail = self._request_parser.feed_data(data)
                               ^^^^^^^^^^^^^^^^^^^^^^^^^^^^^^^^^^^^
  File "aiohttp/_http_parser.pyx", line 557, in aiohttp._http_parser.HttpParser.feed_data
aiohttp.http_exceptions.BadStatusLine: 400, message:
  Invalid method encountered:

    b'\x16\x03\x01\x07\x1e\x01'
      ^
2024-09-19 12:08:14.314 ERROR (MainThread) [aiohttp.server] Error handling request
Traceback (most recent call last):
  File "/usr/local/lib/python3.12/site-packages/aiohttp/web_protocol.py", line 350, in data_received
    messages, upgraded, tail = self._request_parser.feed_data(data)
                               ^^^^^^^^^^^^^^^^^^^^^^^^^^^^^^^^^^^^
  File "aiohttp/_http_parser.pyx", line 557, in aiohttp._http_parser.HttpParser.feed_data
aiohttp.http_exceptions.BadStatusLine: 400, message:
  Invalid method encountered:

    b'\x16\x03\x01\x06\xbe\x01'
      ^
2024-09-19 12:08:14.323 ERROR (MainThread) [aiohttp.server] Error handling request
Traceback (most recent call last):
  File "/usr/local/lib/python3.12/site-packages/aiohttp/web_protocol.py", line 350, in data_received
    messages, upgraded, tail = self._request_parser.feed_data(data)
                               ^^^^^^^^^^^^^^^^^^^^^^^^^^^^^^^^^^^^
  File "aiohttp/_http_parser.pyx", line 557, in aiohttp._http_parser.HttpParser.feed_data
aiohttp.http_exceptions.BadStatusLine: 400, message:
  Invalid method encountered:

    b'\x16\x03\x01\x06\xbe\x01'
      ^
2024-09-19 12:08:14.328 ERROR (MainThread) [aiohttp.server] Error handling request
Traceback (most recent call last):
  File "/usr/local/lib/python3.12/site-packages/aiohttp/web_protocol.py", line 350, in data_received
    messages, upgraded, tail = self._request_parser.feed_data(data)
                               ^^^^^^^^^^^^^^^^^^^^^^^^^^^^^^^^^^^^
  File "aiohttp/_http_parser.pyx", line 557, in aiohttp._http_parser.HttpParser.feed_data
aiohttp.http_exceptions.BadStatusLine: 400, message:
  Invalid method encountered:

    b'\x16\x03\x01\x06\xde\x01'
      ^
2024-09-19 12:08:14.764 ERROR (MainThread) [aiohttp.server] Error handling request
Traceback (most recent call last):
  File "/usr/local/lib/python3.12/site-packages/aiohttp/web_protocol.py", line 350, in data_received
    messages, upgraded, tail = self._request_parser.feed_data(data)
                               ^^^^^^^^^^^^^^^^^^^^^^^^^^^^^^^^^^^^
  File "aiohttp/_http_parser.pyx", line 557, in aiohttp._http_parser.HttpParser.feed_data
aiohttp.http_exceptions.BadStatusLine: 400, message:
  Invalid method encountered:

    b'\x16\x03\x01\x06\xde\x01'
      ^
2024-09-19 12:08:14.769 ERROR (MainThread) [aiohttp.server] Error handling request
Traceback (most recent call last):
  File "/usr/local/lib/python3.12/site-packages/aiohttp/web_protocol.py", line 350, in data_received
    messages, upgraded, tail = self._request_parser.feed_data(data)
                               ^^^^^^^^^^^^^^^^^^^^^^^^^^^^^^^^^^^^
  File "aiohttp/_http_parser.pyx", line 557, in aiohttp._http_parser.HttpParser.feed_data
aiohttp.http_exceptions.BadStatusLine: 400, message:
  Invalid method encountered:

    b'\x16\x03\x01\x06\xbe\x01'
      ^
2024-09-19 12:08:14.778 ERROR (MainThread) [aiohttp.server] Error handling request
Traceback (most recent call last):
  File "/usr/local/lib/python3.12/site-packages/aiohttp/web_protocol.py", line 350, in data_received
    messages, upgraded, tail = self._request_parser.feed_data(data)
                               ^^^^^^^^^^^^^^^^^^^^^^^^^^^^^^^^^^^^
  File "aiohttp/_http_parser.pyx", line 557, in aiohttp._http_parser.HttpParser.feed_data
aiohttp.http_exceptions.BadStatusLine: 400, message:
  Invalid method encountered:

    b'\x16\x03\x01\x07\x1e\x01'
      ^
2024-09-19 12:08:14.788 ERROR (MainThread) [aiohttp.server] Error handling request
Traceback (most recent call last):
  File "/usr/local/lib/python3.12/site-packages/aiohttp/web_protocol.py", line 350, in data_received
    messages, upgraded, tail = self._request_parser.feed_data(data)
                               ^^^^^^^^^^^^^^^^^^^^^^^^^^^^^^^^^^^^
  File "aiohttp/_http_parser.pyx", line 557, in aiohttp._http_parser.HttpParser.feed_data
aiohttp.http_exceptions.BadStatusLine: 400, message:
  Invalid method encountered:

    b'\x16\x03\x01\x06\xde\x01'
      ^
2024-09-19 12:08:14.795 ERROR (MainThread) [aiohttp.server] Error handling request
Traceback (most recent call last):
  File "/usr/local/lib/python3.12/site-packages/aiohttp/web_protocol.py", line 350, in data_received
    messages, upgraded, tail = self._request_parser.feed_data(data)
                               ^^^^^^^^^^^^^^^^^^^^^^^^^^^^^^^^^^^^
  File "aiohttp/_http_parser.pyx", line 557, in aiohttp._http_parser.HttpParser.feed_data
aiohttp.http_exceptions.BadStatusLine: 400, message:
  Invalid method encountered:

    b'\x16\x03\x01\x06\xbe\x01'
      ^
2024-09-19 12:08:14.802 ERROR (MainThread) [aiohttp.server] Error handling request
Traceback (most recent call last):
  File "/usr/local/lib/python3.12/site-packages/aiohttp/web_protocol.py", line 350, in data_received
    messages, upgraded, tail = self._request_parser.feed_data(data)
                               ^^^^^^^^^^^^^^^^^^^^^^^^^^^^^^^^^^^^
  File "aiohttp/_http_parser.pyx", line 557, in aiohttp._http_parser.HttpParser.feed_data
aiohttp.http_exceptions.BadStatusLine: 400, message:
  Invalid method encountered:

    b'\x16\x03\x01\x06\xde\x01'
      ^
2024-09-19 12:08:15.193 ERROR (MainThread) [aiohttp.server] Error handling request
Traceback (most recent call last):
  File "/usr/local/lib/python3.12/site-packages/aiohttp/web_protocol.py", line 350, in data_received
    messages, upgraded, tail = self._request_parser.feed_data(data)
                               ^^^^^^^^^^^^^^^^^^^^^^^^^^^^^^^^^^^^
  File "aiohttp/_http_parser.pyx", line 557, in aiohttp._http_parser.HttpParser.feed_data
aiohttp.http_exceptions.BadStatusLine: 400, message:
  Invalid method encountered:

    b'\x16\x03\x01\x06\xfe\x01'
      ^
2024-09-19 12:08:15.205 ERROR (MainThread) [aiohttp.server] Error handling request
Traceback (most recent call last):
  File "/usr/local/lib/python3.12/site-packages/aiohttp/web_protocol.py", line 350, in data_received
    messages, upgraded, tail = self._request_parser.feed_data(data)
                               ^^^^^^^^^^^^^^^^^^^^^^^^^^^^^^^^^^^^
  File "aiohttp/_http_parser.pyx", line 557, in aiohttp._http_parser.HttpParser.feed_data
aiohttp.http_exceptions.BadStatusLine: 400, message:
  Invalid method encountered:

    b'\x16\x03\x01\x06\xde\x01'
      ^
2024-09-19 12:08:15.210 ERROR (MainThread) [aiohttp.server] Error handling request
Traceback (most recent call last):
  File "/usr/local/lib/python3.12/site-packages/aiohttp/web_protocol.py", line 350, in data_received
    messages, upgraded, tail = self._request_parser.feed_data(data)
                               ^^^^^^^^^^^^^^^^^^^^^^^^^^^^^^^^^^^^
  File "aiohttp/_http_parser.pyx", line 557, in aiohttp._http_parser.HttpParser.feed_data
aiohttp.http_exceptions.BadStatusLine: 400, message:
  Invalid method encountered:

    b'\x16\x03\x01\x06\xde\x01'
      ^
2024-09-19 12:08:15.219 ERROR (MainThread) [aiohttp.server] Error handling request
Traceback (most recent call last):
  File "/usr/local/lib/python3.12/site-packages/aiohttp/web_protocol.py", line 350, in data_received
    messages, upgraded, tail = self._request_parser.feed_data(data)
                               ^^^^^^^^^^^^^^^^^^^^^^^^^^^^^^^^^^^^
  File "aiohttp/_http_parser.pyx", line 557, in aiohttp._http_parser.HttpParser.feed_data
aiohttp.http_exceptions.BadStatusLine: 400, message:
  Invalid method encountered:

    b'\x16\x03\x01\x06\xde\x01'
      ^
2024-09-19 12:08:15.228 ERROR (MainThread) [aiohttp.server] Error handling request
Traceback (most recent call last):
  File "/usr/local/lib/python3.12/site-packages/aiohttp/web_protocol.py", line 350, in data_received
    messages, upgraded, tail = self._request_parser.feed_data(data)
                               ^^^^^^^^^^^^^^^^^^^^^^^^^^^^^^^^^^^^
  File "aiohttp/_http_parser.pyx", line 557, in aiohttp._http_parser.HttpParser.feed_data
aiohttp.http_exceptions.BadStatusLine: 400, message:
  Invalid method encountered:

    b'\x16\x03\x01\x06\xfe\x01'
      ^
2024-09-19 12:08:15.234 ERROR (MainThread) [aiohttp.server] Error handling request
Traceback (most recent call last):
  File "/usr/local/lib/python3.12/site-packages/aiohttp/web_protocol.py", line 350, in data_received
    messages, upgraded, tail = self._request_parser.feed_data(data)
                               ^^^^^^^^^^^^^^^^^^^^^^^^^^^^^^^^^^^^
  File "aiohttp/_http_parser.pyx", line 557, in aiohttp._http_parser.HttpParser.feed_data
aiohttp.http_exceptions.BadStatusLine: 400, message:
  Invalid method encountered:

    b'\x16\x03\x01\x07\x1e\x01'
      ^
2024-09-19 12:08:31.213 ERROR (MainThread) [aiohttp.server] Error handling request
Traceback (most recent call last):
  File "/usr/local/lib/python3.12/site-packages/aiohttp/web_protocol.py", line 350, in data_received
    messages, upgraded, tail = self._request_parser.feed_data(data)
                               ^^^^^^^^^^^^^^^^^^^^^^^^^^^^^^^^^^^^
  File "aiohttp/_http_parser.pyx", line 557, in aiohttp._http_parser.HttpParser.feed_data
aiohttp.http_exceptions.BadStatusLine: 400, message:
  Invalid method encountered:

    b'\x16\x03\x01\x06\xde\x01'
      ^
2024-09-19 12:08:31.237 ERROR (MainThread) [aiohttp.server] Error handling request
Traceback (most recent call last):
  File "/usr/local/lib/python3.12/site-packages/aiohttp/web_protocol.py", line 350, in data_received
    messages, upgraded, tail = self._request_parser.feed_data(data)
                               ^^^^^^^^^^^^^^^^^^^^^^^^^^^^^^^^^^^^
  File "aiohttp/_http_parser.pyx", line 557, in aiohttp._http_parser.HttpParser.feed_data
aiohttp.http_exceptions.BadStatusLine: 400, message:
  Invalid method encountered:

    b'\x16\x03\x01\x06\xbe\x01'
      ^
2024-09-19 13:26:10.241 WARNING (SyncWorker_22) [homeassistant.components.rpi_power.binary_sensor] Under-voltage was detected. Consider getting a uninterruptible power supply for your Raspberry Pi.
